Workbook

Sheet Summary
A1: =Data!$Q$2&" ("&Data!$Q$4&": "&Data!$Q$3&") — Equity Research Summary"
A2: ="Report date "&TEXT(Data!$Q$5,"d-mmm-yyyy")&" · Price $ per share · Financials $ in billions · Fiscal year ends "&Data!$Q$6
A4: VERDICT (MODEL VIEW) | B4: SHARE PRICE | E4: BASE-CASE FAIR VALUE | F4: FAIR-VALUE RANGE (BEAR – BULL)
A5: =IF(Scenarios!B14<-0.15,"Priced above model value",IF(Scenarios!B14>0.15,"Priced below model value","Near model value")) | B5: =DCF!B5 | E5: =Scenarios!C11 | F5: =TEXT(Scenarios!B11,"$0")&" – "&TEXT(Scenarios!D11,"$0")
A6: =IF(Scenarios!D12>0,"Only the bull case clears today's price",IF(Scenarios!B12>0,"Even the bear case is above the price","No scenario reaches today's price")) | B6: ="52-wk "&TEXT(Scenarios!B43,"$0")&"–"&TEXT(Scenarios!B44,"$0") | E6: =TEXT(Scenarios!C12,"+0%;-0%")&" vs price · prob-weighted "&TEXT(Scenarios!B13,"$0") | F6: ="Price needs "&IFERROR(TEXT(DCF!B82,"0%"),"n/a")&" op. margin (today "&TEXT(DCF!B39,"0%")&")"
A8: Market snapshot | E8: Intrinsic value (DCF)
A9: Share price | B9: =IFERROR(DCF!B5,"n/a") | F9: Bear | G9: Base | H9: Bull
A10: Market capitalisation ($B) | B10: =IFERROR(Multiples!B7,"n/a") | E10: Fair value / share | F10: =Scenarios!B11 | G10: =Scenarios!C11 | H10: =Scenarios!D11
A11: Enterprise value ($B) | B11: =IFERROR(Multiples!B9,"n/a") | E11: vs current price | F11: =Scenarios!B12 | G11: =Scenarios!C12 | H11: =Scenarios!D12
A12: 52-week low | B12: =IFERROR(Risk!B30,"n/a") | E12: Scenario weight | F12: =Scenarios!B10 | G12: =Scenarios!C10 | H12: =Scenarios!D10
A13: 52-week high | B13: =IFERROR(Risk!B29,"n/a") | E13: Probability-weighted value | F13: =Scenarios!B13
A14: =TEXT(Data!A1256,"yyyy")&" YTD total return" | B14: =Risk!C43 | E14: Upside / (downside) | F14: =Scenarios!B14
A15: Dividend yield | B15: =IFERROR(Multiples!B11,"n/a")
A16: ="Net cash ($B, "&TEXT(Financials!E16,"d-mmm-yy")&")" | B16: =IFERROR(Financials!C39,"n/a") | E16: What is the market pricing in? (reverse DCF)
E17: Implied year-1 revenue growth | F17: =DCF!B79
A18: Valuation multiples | E18: Implied 10-yr revenue CAGR | F18: =DCF!B80
B19: =IFERROR(Financials!K5,"n/a") | C19: TTM | E19: ="Actual 5-yr CAGR ("&Financials!F5&"–"&Financials!K5&")" | F19: =DCF!B83
A20: P/E (FY GAAP · TTM excl. gains) | B20: =IFERROR(Multiples!B15,"n/a") | C20: =IFERROR(Multiples!C16,"n/a") | E20: Implied long-run operating margin | F20: =DCF!B82 | G20: ="vs today "&IFERROR(TEXT(DCF!B39,"0%"),"n/a")&IFERROR(" · peers "&TEXT(MEDIAN(Peers!H7:H10),"0%"),"")
A21: Price / Sales | B21: =IFERROR(Multiples!B18,"n/a") | C21: =IFERROR(Multiples!C18,"n/a")
A22: EV / EBITDA | B22: =IFERROR(Multiples!B19,"n/a") | C22: =IFERROR(Multiples!C19,"n/a") | E22: Analyst view
A23: FCF yield | B23: =IFERROR(Multiples!B21,"n/a") | C23: =IFERROR(Multiples!C21,"n/a") | E23: ="At "&TEXT(B9,"$0")&", "&Data!$Q$2&IF(N(C20)>0," trades at "&TEXT(C20,"0.0x")&" trailing earnings"&IF(Financials!F19-Financials!F27>0.005," excluding one-off investment gains ("&TEXT(Multiples!C15,"0.0x")&" GAAP)","")&IFERROR(", vs a historical average of "&TEXT(Valuation_History!D17,"0.0x"),"")," has no trailing earnings to price")&". The base-case DCF ("&TEXT(G10,"$0")&", "&TEXT(G11,"+0%;-0%")&") assumes "&TEXT(DCF!B9,"0%")&" year-1 revenue growth fading to "&TEXT(DCF!B8,"0.0%")&", a "&TEXT(DCF!B10,"0%")&" operating margin, and capex "&IF(DCF!B19<DCF!B40,"easing","rising")&" from "&TEXT(DCF!B40,"0%")&" to "&TEXT(DCF!B19,"0%")&" of revenue. To justify the price the market needs "&IFERROR(TEXT(DCF!B79,"0%")&" year-1 growth","growth beyond the solvable range")&" or a "&IFERROR(TEXT(DCF!B82,"0%"),"n/a")&" long-run operating margin. "&IF(H11<0,"No scenario reaches the price.",IF(F11>0,"Even the bear case is above the price.","The price sits between the bear ("&TEXT(F10,"$0")&") and bull ("&TEXT(H10,"$0")&") cases; probability-weighted value "&TEXT(F13,"$0")&" ("&TEXT(F14,"+0%;-0%")&")."))
A24: FCF yield after stock comp | B24: =IFERROR(Multiples!B22,"n/a") | C24: =IFERROR(Multiples!C22,"n/a")
A26: Fundamentals
A27: ="Revenue, TTM to "&TEXT(Financials!E16,"mmm-yyyy")&" ($B)" | B27: =IFERROR(Financials!F17,"n/a")
A28: Revenue growth, last 3 qtrs avg y/y | B28: =IFERROR(DCF!B84,"n/a")
A29: Diluted EPS TTM ($) · GAAP / excl. gains | B29: =IFERROR(Financials!F19,"n/a") | C29: =IFERROR(Financials!F27,"n/a")
A30: Gross margin, TTM | B30: =IFERROR(Multiples!C28,"n/a") | C30: =IFERROR("to "&TEXT(Financials!E16,"d-mmm-yy"),"n/a")
A31: ="Free cash flow "&Financials!K5&" ($B)" | B31: =IFERROR(Financials!K10,"n/a") | E31: ="Stance: valuation view, no rating. Reference value = base case "&TEXT(Scenarios!C11,"$0")&" (probability-weighted "&TEXT(Scenarios!B13,"$0")&"). Not investment advice."
A32: ="9-year FCF CAGR ("&Financials!B5&"–"&Financials!K5&")" | B32: =IFERROR(Financials!L10,"n/a")
A34: Bull case, bear case, catalysts and risks
A35: Bull case | D35: Bear case
A36: ="• Revenue growth ran "&TEXT(MIN(Financials!C18:E18),"+0%;-0%")&" to "&TEXT(MAX(Financials!C18:E18),"+0%;-0%")&" y/y over the last three quarters"&IF(Data!$Q$9="","",", "&Data!$Q$9)&"." | D36: ="• "&Data!$Q$10
A37: ="• "&Data!$Q$8 | D37: =IF(Financials!C56>Financials!B56*1.005,"• Dilution: "&Data!$Q$11&" lifted the share count to "&TEXT(Financials!C56,"0.00")&"B from "&TEXT(Financials!B56,"0.00")&"B at "&Financials!K5&".",IF(Financials!C56<Financials!B56*0.995,"• Share count "&TEXT(Financials!C56,"0.00")&"B vs "&TEXT(Financials!B56,"0.00")&"B at "&Financials!K5&" — buybacks are shrinking the base.","• Share count steady at "&TEXT(Financials!C56,"0.00")&"B; "&Data!$Q$11&"."))
A38: =IFERROR("• Gross margin "&IF(Multiples!C28>=Multiples!B28,"widened","narrowed")&" to "&TEXT(Multiples!C28,"0.0%")&" TTM from "&TEXT(Multiples!B28,"0.0%")&" in "&Financials!K5&"; operating margin is "&TEXT(Financials!F23,"0.0%")&".","• Operating margin is "&TEXT(Financials!F23,"0.0%")&" over the last twelve months.") | D38: ="• Capex runs at "&TEXT(DCF!B40,"0%")&" of revenue"&IF(Data!$Q$12="",""," ("&Data!$Q$12&")")&"; the TTM FCF margin is "&TEXT(DCF!B38,"0.0%")&" vs "&TEXT(Financials!K11,"0.0%")&" in "&Financials!K5&"."
A39: ="• $"&TEXT(Financials!C35,"#,##0")&"B of cash and securities ("&IF(Financials!C39>=0,"net cash $"&TEXT(Financials!C39,"#,##0")&"B","net debt $"&TEXT(-Financials!C39,"#,##0")&"B")&")"&IF(Financials!C54>0," plus $"&TEXT(Financials!C54,"#,##0")&"B of private equity stakes not captured by FCF","")&"." | D39: ="• Stock-based pay of $"&TEXT(Financials!C44,"0.0")&"B ("&TEXT(Multiples!C35,"0%")&" of TTM FCF) is added back in reported free cash flow."
A41: Upcoming catalysts | D41: What drives the answer
A42: ="• "&Data!$Q$13 | D42: ="• The result rests on the long-run operating margin ("&TEXT(DCF!B10,"0.0%")&", "&DCF!B17&" anchor). Each +1 pt adds ~$"&TEXT((Scenarios!F31-Scenarios!E31)/((Scenarios!F28-Scenarios!E28)*100),"0")&" per share."
A43: ="• "&Data!$Q$14 | D43: ="• The terminal value implies "&TEXT(DCF!B96,"0.0x")&" EV/EBITDA — "&IF(DCF!B96<8,"conservative against the ~10–20x mature companies trade at, so the base case leans cautious.",IF(DCF!B96>25,"aggressive; the base case may be too generous.","within the normal range for mature companies."))
A44: ="• "&Data!$Q$15 | D44: ="• Model integrity: "&DCF!B109&" (DCF sanity checks, rows 91–109)."
A45: ="• "&Data!$Q$16 | D45: ="• Data: prices to "&TEXT(Data!A1256,"d-mmm-yyyy")&"; balance sheet "&TEXT(Financials!E16,"d-mmm-yyyy")&". "&IF(Financials!F19-Financials!F27>0.005,"TTM EPS excludes $"&TEXT(Financials!F19-Financials!F27,"0.00")&" of investment gains.","No investment-gain adjustment needed.")
...

Sheet Scenarios
A1: =Data!$Q$2&" ("&Data!$Q$3&") — Scenarios & Sensitivity"
A2: Every value on this tab is live: it recalculates from the DCF tab inputs · $ per share | G2: ← Back to Summary
A4: Bear / base / bull scenarios
B5: Bear | C5: Base | D5: Bull | F5: Bear / bull spread (±)
A6: Year-1 revenue growth (fades to terminal) | B6: =C6-$F6 | C6: =DCF!B9 | D6: =C6+$F6 | E6: Bear/bull = base ∓ the spread in column F (blue). Spreads scale with the company: the margin swing is a quarter of the base margin (1–5 points) and the growth swing 40% of base growth (2–6 points). Capex, D&A and timing follow the DCF tab. | F6: 0.02
A7: Long-run operating margin | B7: =C7-$F7 | C7: =DCF!B10 | D7: =C7+$F7 | F7: 0.02
A8: Discount rate (WACC) | B8: =C8+$F8 | C8: =DCF!B7 | D8: =C8-$F8 | F8: 0.01
A9: Terminal growth | B9: =C9-$F9 | C9: =DCF!B8 | D9: =C9+$F9 | F9: 0.005
A10: Scenario probability | B10: 0.25 | C10: 0.5 | D10: 0.25 | E10: =IF(ABS(SUM(B10:D10)-1)<0.0001,"✓ sums to 100%","⚠ must sum to 100%")
A11: Fair value per share ($) | B11: {=_xlfn.LET(_xlpm.gs,B6,_xlpm.om,B7,_xlpm.w,B8,_xlpm.tgr,B9,_xlpm.n,DCF!$B$11,_xlpm.lcx,DCF!$B$19,_xlpm.r0,DCF!$B$37,_xlpm.om0,DCF!$B$39,_xlpm.cx0,DCF!$B$40,_xlpm.da0,DCF!$B$41,_xlpm.dar,DCF!$B$20,_xlpm.tx,DCF!$B$31,_xlpm.sb,DCF!$B$43,_xlpm.nw,DCF!$B$21,_xlpm.gd,N(DCF!$B$22),_xlpm.nc,DCF!$B$47,_xlpm.shs,DCF!$B$6,_xlpm.m,DCF!$B$48,_xlpm.t,_xlfn.SEQUENCE(10),_xlpm.g,_xlpm.gs-(_xlpm.gs-_xlpm.tgr)*(_xlpm.t-1)/9,_xlpm.cum,MMULT(--(_xlpm.t>=TRANSPOSE(_xlpm.t)),LN(1+_xlpm.g)),_xlpm.rev,_xlpm.r0*EXP(_xlpm.cum),_xlpm.prv,_xlpm.r0*EXP(_xlpm.cum-LN(1+_xlpm.g)),_xlpm.lp,IF(_xlpm.t>=_xlpm.n,1,_xlpm.t/_xlpm.n),_xlpm.omt,_xlpm.om0+(_xlpm.om-_xlpm.om0)*_xlpm.lp,_xlpm.dat,_xlpm.da0+(_xlpm.lcx*_xlpm.dar-_xlpm.da0)*_xlpm.lp,_xlpm.cpx,IF((_xlpm.t=1)*(_xlpm.gd>0),_xlpm.gd/_xlpm.rev,_xlpm.cx0+(_xlpm.lcx-_xlpm.cx0)*_xlpm.lp),_xlpm.f,_xlpm.rev*(_xlpm.omt*(1-_xlpm.tx)+_xlpm.dat-_xlpm.cpx+_xlpm.sb)-_xlpm.nw*(_xlpm.rev-_xlpm.prv),_xlpm.pv,SUM(_xlpm.f/(1+_xlpm.w)^(_xlpm.t-0.5*_xlpm.m)),_xlpm.tv,INDEX(_xlpm.f,10)*(1+_xlpm.tgr)/(_xlpm.w-_xlpm.tgr)/(1+_xlpm.w)^10,(_xlpm.pv+_xlpm.tv+_xlpm.nc)/_xlpm.shs)} | C11: {=_xlfn.LET(_xlpm.gs,C6,_xlpm.om,C7,_xlpm.w,C8,_xlpm.tgr,C9,_xlpm.n,DCF!$B$11,_xlpm.lcx,DCF!$B$19,_xlpm.r0,DCF!$B$37,_xlpm.om0,DCF!$B$39,_xlpm.cx0,DCF!$B$40,_xlpm.da0,DCF!$B$41,_xlpm.dar,DCF!$B$20,_xlpm.tx,DCF!$B$31,_xlpm.sb,DCF!$B$43,_xlpm.nw,DCF!$B$21,_xlpm.gd,N(DCF!$B$22),_xlpm.nc,DCF!$B$47,_xlpm.shs,DCF!$B$6,_xlpm.m,DCF!$B$48,_xlpm.t,_xlfn.SEQUENCE(10),_xlpm.g,_xlpm.gs-(_xlpm.gs-_xlpm.tgr)*(_xlpm.t-1)/9,_xlpm.cum,MMULT(--(_xlpm.t>=TRANSPOSE(_xlpm.t)),LN(1+_xlpm.g)),_xlpm.rev,_xlpm.r0*EXP(_xlpm.cum),_xlpm.prv,_xlpm.r0*EXP(_xlpm.cum-LN(1+_xlpm.g)),_xlpm.lp,IF(_xlpm.t>=_xlpm.n,1,_xlpm.t/_xlpm.n),_xlpm.omt,_xlpm.om0+(_xlpm.om-_xlpm.om0)*_xlpm.lp,_xlpm.dat,_xlpm.da0+(_xlpm.lcx*_xlpm.dar-_xlpm.da0)*_xlpm.lp,_xlpm.cpx,IF((_xlpm.t=1)*(_xlpm.gd>0),_xlpm.gd/_xlpm.rev,_xlpm.cx0+(_xlpm.lcx-_xlpm.cx0)*_xlpm.lp),_xlpm.f,_xlpm.rev*(_xlpm.omt*(1-_xlpm.tx)+_xlpm.dat-_xlpm.cpx+_xlpm.sb)-_xlpm.nw*(_xlpm.rev-_xlpm.prv),_xlpm.pv,SUM(_xlpm.f/(1+_xlpm.w)^(_xlpm.t-0.5*_xlpm.m)),_xlpm.tv,INDEX(_xlpm.f,10)*(1+_xlpm.tgr)/(_xlpm.w-_xlpm.tgr)/(1+_xlpm.w)^10,(_xlpm.pv+_xlpm.tv+_xlpm.nc)/_xlpm.shs)} | D11: {=_xlfn.LET(_xlpm.gs,D6,_xlpm.om,D7,_xlpm.w,D8,_xlpm.tgr,D9,_xlpm.n,DCF!$B$11,_xlpm.lcx,DCF!$B$19,_xlpm.r0,DCF!$B$37,_xlpm.om0,DCF!$B$39,_xlpm.cx0,DCF!$B$40,_xlpm.da0,DCF!$B$41,_xlpm.dar,DCF!$B$20,_xlpm.tx,DCF!$B$31,_xlpm.sb,DCF!$B$43,_xlpm.nw,DCF!$B$21,_xlpm.gd,N(DCF!$B$22),_xlpm.nc,DCF!$B$47,_xlpm.shs,DCF!$B$6,_xlpm.m,DCF!$B$48,_xlpm.t,_xlfn.SEQUENCE(10),_xlpm.g,_xlpm.gs-(_xlpm.gs-_xlpm.tgr)*(_xlpm.t-1)/9,_xlpm.cum,MMULT(--(_xlpm.t>=TRANSPOSE(_xlpm.t)),LN(1+_xlpm.g)),_xlpm.rev,_xlpm.r0*EXP(_xlpm.cum),_xlpm.prv,_xlpm.r0*EXP(_xlpm.cum-LN(1+_xlpm.g)),_xlpm.lp,IF(_xlpm.t>=_xlpm.n,1,_xlpm.t/_xlpm.n),_xlpm.omt,_xlpm.om0+(_xlpm.om-_xlpm.om0)*_xlpm.lp,_xlpm.dat,_xlpm.da0+(_xlpm.lcx*_xlpm.dar-_xlpm.da0)*_xlpm.lp,_xlpm.cpx,IF((_xlpm.t=1)*(_xlpm.gd>0),_xlpm.gd/_xlpm.rev,_xlpm.cx0+(_xlpm.lcx-_xlpm.cx0)*_xlpm.lp),_xlpm.f,_xlpm.rev*(_xlpm.omt*(1-_xlpm.tx)+_xlpm.dat-_xlpm.cpx+_xlpm.sb)-_xlpm.nw*(_xlpm.rev-_xlpm.prv),_xlpm.pv,SUM(_xlpm.f/(1+_xlpm.w)^(_xlpm.t-0.5*_xlpm.m)),_xlpm.tv,INDEX(_xlpm.f,10)*(1+_xlpm.tgr)/(_xlpm.w-_xlpm.tgr)/(1+_xlpm.w)^10,(_xlpm.pv+_xlpm.tv+_xlpm.nc)/_xlpm.shs)}
A12: Upside / (downside) vs price | B12: =B11/DCF!$B$5-1 | C12: =C11/DCF!$B$5-1 | D12: =D11/DCF!$B$5-1
A13: Probability-weighted fair value ($) | B13: =SUMPRODUCT(B10:D10,B11:D11)
A14: Probability-weighted upside / (downside) | B14: =B13/DCF!B5-1
A15: What has to happen | B15: ="Growth slows: revenue "&TEXT(B6,"+0%;-0%")&" in year one, operating margin settles at "&TEXT(B7,"0%")&" (vs "&TEXT(DCF!$B$39,"0%")&" today) and a "&TEXT(B8,"0.0%")&" discount rate prices in more risk." | C15: ="Revenue "&TEXT(C6,"+0%;-0%")&" in year one, fading to "&TEXT(C9,"0.0%")&"; operating margin "&TEXT(C7,"0%")&" ("&DCF!$B$17&" anchor); capex "&IF(DCF!$B$19<DCF!$B$40,"falls","rises")&" from "&TEXT(DCF!$B$40,"0%")&" to "&TEXT(DCF!$B$19,"0%")&" of revenue by year "&DCF!$B$11&"." | D15: ="Momentum holds: revenue "&TEXT(D6,"+0%;-0%")&" in year one, operating margin expands to "&TEXT(D7,"0%")&" as investment pays off, with a "&TEXT(D8,"0.0%")&" WACC and "&TEXT(D9,"0.0%")&" terminal growth."
A19: Sensitivity 1 — fair value per share: WACC (rows) × terminal growth (columns), base-case growth and margin
B20: WACC ↓ · g → | C20: =DCF!$B$8+(-0.01) | D20: =DCF!$B$8+(-0.005) | E20: =DCF!$B$8+(0) | F20: =DCF!$B$8+(0.005) | G20: =DCF!$B$8+(0.01)
B21: =DCF!$B$7+(-0.01) | C21: {=_xlfn.LET(_xlpm.gs,DCF!$B$9,_xlpm.om,DCF!$B$10,_xlpm.w,$B21,_xlpm.tgr,C$20,_xlpm.n,DCF!$B$11,_xlpm.lcx,DCF!$B$19,_xlpm.r0,DCF!$B$37,_xlpm.om0,DCF!$B$39,_xlpm.cx0,DCF!$B$40,_xlpm.da0,DCF!$B$41,_xlpm.dar,DCF!$B$20,_xlpm.tx,DCF!$B$31,_xlpm.sb,DCF!$B$43,_xlpm.nw,DCF!$B$21,_xlpm.gd,N(DCF!$B$22),_xlpm.nc,DCF!$B$47,_xlpm.shs,DCF!$B$6,_xlpm.m,DCF!$B$48,_xlpm.t,_xlfn.SEQUENCE(10),_xlpm.g,_xlpm.gs-(_xlpm.gs-_xlpm.tgr)*(_xlpm.t-1)/9,_xlpm.cum,MMULT(--(_xlpm.t>=TRANSPOSE(_xlpm.t)),LN(1+_xlpm.g)),_xlpm.rev,_xlpm.r0*EXP(_xlpm.cum),_xlpm.prv,_xlpm.r0*EXP(_xlpm.cum-LN(1+_xlpm.g)),_xlpm.lp,IF(_xlpm.t>=_xlpm.n,1,_xlpm.t/_xlpm.n),_xlpm.omt,_xlpm.om0+(_xlpm.om-_xlpm.om0)*_xlpm.lp,_xlpm.dat,_xlpm.da0+(_xlpm.lcx*_xlpm.dar-_xlpm.da0)*_xlpm.lp,_xlpm.cpx,IF((_xlpm.t=1)*(_xlpm.gd>0),_xlpm.gd/_xlpm.rev,_xlpm.cx0+(_xlpm.lcx-_xlpm.cx0)*_xlpm.lp),_xlpm.f,_xlpm.rev*(_xlpm.omt*(1-_xlpm.tx)+_xlpm.dat-_xlpm.cpx+_xlpm.sb)-_xlpm.nw*(_xlpm.rev-_xlpm.prv),_xlpm.pv,SUM(_xlpm.f/(1+_xlpm.w)^(_xlpm.t-0.5*_xlpm.m)),_xlpm.tv,INDEX(_xlpm.f,10)*(1+_xlpm.tgr)/(_xlpm.w-_xlpm.tgr)/(1+_xlpm.w)^10,(_xlpm.pv+_xlpm.tv+_xlpm.nc)/_xlpm.shs)} | D21: {=_xlfn.LET(_xlpm.gs,DCF!$B$9,_xlpm.om,DCF!$B$10,_xlpm.w,$B21,_xlpm.tgr,D$20,_xlpm.n,DCF!$B$11,_xlpm.lcx,DCF!$B$19,_xlpm.r0,DCF!$B$37,_xlpm.om0,DCF!$B$39,_xlpm.cx0,DCF!$B$40,_xlpm.da0,DCF!$B$41,_xlpm.dar,DCF!$B$20,_xlpm.tx,DCF!$B$31,_xlpm.sb,DCF!$B$43,_xlpm.nw,DCF!$B$21,_xlpm.gd,N(DCF!$B$22),_xlpm.nc,DCF!$B$47,_xlpm.shs,DCF!$B$6,_xlpm.m,DCF!$B$48,_xlpm.t,_xlfn.SEQUENCE(10),_xlpm.g,_xlpm.gs-(_xlpm.gs-_xlpm.tgr)*(_xlpm.t-1)/9,_xlpm.cum,MMULT(--(_xlpm.t>=TRANSPOSE(_xlpm.t)),LN(1+_xlpm.g)),_xlpm.rev,_xlpm.r0*EXP(_xlpm.cum),_xlpm.prv,_xlpm.r0*EXP(_xlpm.cum-LN(1+_xlpm.g)),_xlpm.lp,IF(_xlpm.t>=_xlpm.n,1,_xlpm.t/_xlpm.n),_xlpm.omt,_xlpm.om0+(_xlpm.om-_xlpm.om0)*_xlpm.lp,_xlpm.dat,_xlpm.da0+(_xlpm.lcx*_xlpm.dar-_xlpm.da0)*_xlpm.lp,_xlpm.cpx,IF((_xlpm.t=1)*(_xlpm.gd>0),_xlpm.gd/_xlpm.rev,_xlpm.cx0+(_xlpm.lcx-_xlpm.cx0)*_xlpm.lp),_xlpm.f,_xlpm.rev*(_xlpm.omt*(1-_xlpm.tx)+_xlpm.dat-_xlpm.cpx+_xlpm.sb)-_xlpm.nw*(_xlpm.rev-_xlpm.prv),_xlpm.pv,SUM(_xlpm.f/(1+_xlpm.w)^(_xlpm.t-0.5*_xlpm.m)),_xlpm.tv,INDEX(_xlpm.f,10)*(1+_xlpm.tgr)/(_xlpm.w-_xlpm.tgr)/(1+_xlpm.w)^10,(_xlpm.pv+_xlpm.tv+_xlpm.nc)/_xlpm.shs)} | E21: {=_xlfn.LET(_xlpm.gs,DCF!$B$9,_xlpm.om,DCF!$B$10,_xlpm.w,$B21,_xlpm.tgr,E$20,_xlpm.n,DCF!$B$11,_xlpm.lcx,DCF!$B$19,_xlpm.r0,DCF!$B$37,_xlpm.om0,DCF!$B$39,_xlpm.cx0,DCF!$B$40,_xlpm.da0,DCF!$B$41,_xlpm.dar,DCF!$B$20,_xlpm.tx,DCF!$B$31,_xlpm.sb,DCF!$B$43,_xlpm.nw,DCF!$B$21,_xlpm.gd,N(DCF!$B$22),_xlpm.nc,DCF!$B$47,_xlpm.shs,DCF!$B$6,_xlpm.m,DCF!$B$48,_xlpm.t,_xlfn.SEQUENCE(10),_xlpm.g,_xlpm.gs-(_xlpm.gs-_xlpm.tgr)*(_xlpm.t-1)/9,_xlpm.cum,MMULT(--(_xlpm.t>=TRANSPOSE(_xlpm.t)),LN(1+_xlpm.g)),_xlpm.rev,_xlpm.r0*EXP(_xlpm.cum),_xlpm.prv,_xlpm.r0*EXP(_xlpm.cum-LN(1+_xlpm.g)),_xlpm.lp,IF(_xlpm.t>=_xlpm.n,1,_xlpm.t/_xlpm.n),_xlpm.omt,_xlpm.om0+(_xlpm.om-_xlpm.om0)*_xlpm.lp,_xlpm.dat,_xlpm.da0+(_xlpm.lcx*_xlpm.dar-_xlpm.da0)*_xlpm.lp,_xlpm.cpx,IF((_xlpm.t=1)*(_xlpm.gd>0),_xlpm.gd/_xlpm.rev,_xlpm.cx0+(_xlpm.lcx-_xlpm.cx0)*_xlpm.lp),_xlpm.f,_xlpm.rev*(_xlpm.omt*(1-_xlpm.tx)+_xlpm.dat-_xlpm.cpx+_xlpm.sb)-_xlpm.nw*(_xlpm.rev-_xlpm.prv),_xlpm.pv,SUM(_xlpm.f/(1+_xlpm.w)^(_xlpm.t-0.5*_xlpm.m)),_xlpm.tv,INDEX(_xlpm.f,10)*(1+_xlpm.tgr)/(_xlpm.w-_xlpm.tgr)/(1+_xlpm.w)^10,(_xlpm.pv+_xlpm.tv+_xlpm.nc)/_xlpm.shs)} | F21: {=_xlfn.LET(_xlpm.gs,DCF!$B$9,_xlpm.om,DCF!$B$10,_xlpm.w,$B21,_xlpm.tgr,F$20,_xlpm.n,DCF!$B$11,_xlpm.lcx,DCF!$B$19,_xlpm.r0,DCF!$B$37,_xlpm.om0,DCF!$B$39,_xlpm.cx0,DCF!$B$40,_xlpm.da0,DCF!$B$41,_xlpm.dar,DCF!$B$20,_xlpm.tx,DCF!$B$31,_xlpm.sb,DCF!$B$43,_xlpm.nw,DCF!$B$21,_xlpm.gd,N(DCF!$B$22),_xlpm.nc,DCF!$B$47,_xlpm.shs,DCF!$B$6,_xlpm.m,DCF!$B$48,_xlpm.t,_xlfn.SEQUENCE(10),_xlpm.g,_xlpm.gs-(_xlpm.gs-_xlpm.tgr)*(_xlpm.t-1)/9,_xlpm.cum,MMULT(--(_xlpm.t>=TRANSPOSE(_xlpm.t)),LN(1+_xlpm.g)),_xlpm.rev,_xlpm.r0*EXP(_xlpm.cum),_xlpm.prv,_xlpm.r0*EXP(_xlpm.cum-LN(1+_xlpm.g)),_xlpm.lp,IF(_xlpm.t>=_xlpm.n,1,_xlpm.t/_xlpm.n),_xlpm.omt,_xlpm.om0+(_xlpm.om-_xlpm.om0)*_xlpm.lp,_xlpm.dat,_xlpm.da0+(_xlpm.lcx*_xlpm.dar-_xlpm.da0)*_xlpm.lp,_xlpm.cpx,IF((_xlpm.t=1)*(_xlpm.gd>0),_xlpm.gd/_xlpm.rev,_xlpm.cx0+(_xlpm.lcx-_xlpm.cx0)*_xlpm.lp),_xlpm.f,_xlpm.rev*(_xlpm.omt*(1-_xlpm.tx)+_xlpm.dat-_xlpm.cpx+_xlpm.sb)-_xlpm.nw*(_xlpm.rev-_xlpm.prv),_xlpm.pv,SUM(_xlpm.f/(1+_xlpm.w)^(_xlpm.t-0.5*_xlpm.m)),_xlpm.tv,INDEX(_xlpm.f,10)*(1+_xlpm.tgr)/(_xlpm.w-_xlpm.tgr)/(1+_xlpm.w)^10,(_xlpm.pv+_xlpm.tv+_xlpm.nc)/_xlpm.shs)} | G21: {=_xlfn.LET(_xlpm.gs,DCF!$B$9,_xlpm.om,DCF!$B$10,_xlpm.w,$B21,_xlpm.tgr,G$20,_xlpm.n,DCF!$B$11,_xlpm.lcx,DCF!$B$19,_xlpm.r0,DCF!$B$37,_xlpm.om0,DCF!$B$39,_xlpm.cx0,DCF!$B$40,_xlpm.da0,DCF!$B$41,_xlpm.dar,DCF!$B$20,_xlpm.tx,DCF!$B$31,_xlpm.sb,DCF!$B$43,_xlpm.nw,DCF!$B$21,_xlpm.gd,N(DCF!$B$22),_xlpm.nc,DCF!$B$47,_xlpm.shs,DCF!$B$6,_xlpm.m,DCF!$B$48,_xlpm.t,_xlfn.SEQUENCE(10),_xlpm.g,_xlpm.gs-(_xlpm.gs-_xlpm.tgr)*(_xlpm.t-1)/9,_xlpm.cum,MMULT(--(_xlpm.t>=TRANSPOSE(_xlpm.t)),LN(1+_xlpm.g)),_xlpm.rev,_xlpm.r0*EXP(_xlpm.cum),_xlpm.prv,_xlpm.r0*EXP(_xlpm.cum-LN(1+_xlpm.g)),_xlpm.lp,IF(_xlpm.t>=_xlpm.n,1,_xlpm.t/_xlpm.n),_xlpm.omt,_xlpm.om0+(_xlpm.om-_xlpm.om0)*_xlpm.lp,_xlpm.dat,_xlpm.da0+(_xlpm.lcx*_xlpm.dar-_xlpm.da0)*_xlpm.lp,_xlpm.cpx,IF((_xlpm.t=1)*(_xlpm.gd>0),_xlpm.gd/_xlpm.rev,_xlpm.cx0+(_xlpm.lcx-_xlpm.cx0)*_xlpm.lp),_xlpm.f,_xlpm.rev*(_xlpm.omt*(1-_xlpm.tx)+_xlpm.dat-_xlpm.cpx+_xlpm.sb)-_xlpm.nw*(_xlpm.rev-_xlpm.prv),_xlpm.pv,SUM(_xlpm.f/(1+_xlpm.w)^(_xlpm.t-0.5*_xlpm.m)),_xlpm.tv,INDEX(_xlpm.f,10)*(1+_xlpm.tgr)/(_xlpm.w-_xlpm.tgr)/(1+_xlpm.w)^10,(_xlpm.pv+_xlpm.tv+_xlpm.nc)/_xlpm.shs)}
B22: =DCF!$B$7+(-0.005) | C22: {=_xlfn.LET(_xlpm.gs,DCF!$B$9,_xlpm.om,DCF!$B$10,_xlpm.w,$B22,_xlpm.tgr,C$20,_xlpm.n,DCF!$B$11,_xlpm.lcx,DCF!$B$19,_xlpm.r0,DCF!$B$37,_xlpm.om0,DCF!$B$39,_xlpm.cx0,DCF!$B$40,_xlpm.da0,DCF!$B$41,_xlpm.dar,DCF!$B$20,_xlpm.tx,DCF!$B$31,_xlpm.sb,DCF!$B$43,_xlpm.nw,DCF!$B$21,_xlpm.gd,N(DCF!$B$22),_xlpm.nc,DCF!$B$47,_xlpm.shs,DCF!$B$6,_xlpm.m,DCF!$B$48,_xlpm.t,_xlfn.SEQUENCE(10),_xlpm.g,_xlpm.gs-(_xlpm.gs-_xlpm.tgr)*(_xlpm.t-1)/9,_xlpm.cum,MMULT(--(_xlpm.t>=TRANSPOSE(_xlpm.t)),LN(1+_xlpm.g)),_xlpm.rev,_xlpm.r0*EXP(_xlpm.cum),_xlpm.prv,_xlpm.r0*EXP(_xlpm.cum-LN(1+_xlpm.g)),_xlpm.lp,IF(_xlpm.t>=_xlpm.n,1,_xlpm.t/_xlpm.n),_xlpm.omt,_xlpm.om0+(_xlpm.om-_xlpm.om0)*_xlpm.lp,_xlpm.dat,_xlpm.da0+(_xlpm.lcx*_xlpm.dar-_xlpm.da0)*_xlpm.lp,_xlpm.cpx,IF((_xlpm.t=1)*(_xlpm.gd>0),_xlpm.gd/_xlpm.rev,_xlpm.cx0+(_xlpm.lcx-_xlpm.cx0)*_xlpm.lp),_xlpm.f,_xlpm.rev*(_xlpm.omt*(1-_xlpm.tx)+_xlpm.dat-_xlpm.cpx+_xlpm.sb)-_xlpm.nw*(_xlpm.rev-_xlpm.prv),_xlpm.pv,SUM(_xlpm.f/(1+_xlpm.w)^(_xlpm.t-0.5*_xlpm.m)),_xlpm.tv,INDEX(_xlpm.f,10)*(1+_xlpm.tgr)/(_xlpm.w-_xlpm.tgr)/(1+_xlpm.w)^10,(_xlpm.pv+_xlpm.tv+_xlpm.nc)/_xlpm.shs)} | D22: {=_xlfn.LET(_xlpm.gs,DCF!$B$9,_xlpm.om,DCF!$B$10,_xlpm.w,$B22,_xlpm.tgr,D$20,_xlpm.n,DCF!$B$11,_xlpm.lcx,DCF!$B$19,_xlpm.r0,DCF!$B$37,_xlpm.om0,DCF!$B$39,_xlpm.cx0,DCF!$B$40,_xlpm.da0,DCF!$B$41,_xlpm.dar,DCF!$B$20,_xlpm.tx,DCF!$B$31,_xlpm.sb,DCF!$B$43,_xlpm.nw,DCF!$B$21,_xlpm.gd,N(DCF!$B$22),_xlpm.nc,DCF!$B$47,_xlpm.shs,DCF!$B$6,_xlpm.m,DCF!$B$48,_xlpm.t,_xlfn.SEQUENCE(10),_xlpm.g,_xlpm.gs-(_xlpm.gs-_xlpm.tgr)*(_xlpm.t-1)/9,_xlpm.cum,MMULT(--(_xlpm.t>=TRANSPOSE(_xlpm.t)),LN(1+_xlpm.g)),_xlpm.rev,_xlpm.r0*EXP(_xlpm.cum),_xlpm.prv,_xlpm.r0*EXP(_xlpm.cum-LN(1+_xlpm.g)),_xlpm.lp,IF(_xlpm.t>=_xlpm.n,1,_xlpm.t/_xlpm.n),_xlpm.omt,_xlpm.om0+(_xlpm.om-_xlpm.om0)*_xlpm.lp,_xlpm.dat,_xlpm.da0+(_xlpm.lcx*_xlpm.dar-_xlpm.da0)*_xlpm.lp,_xlpm.cpx,IF((_xlpm.t=1)*(_xlpm.gd>0),_xlpm.gd/_xlpm.rev,_xlpm.cx0+(_xlpm.lcx-_xlpm.cx0)*_xlpm.lp),_xlpm.f,_xlpm.rev*(_xlpm.omt*(1-_xlpm.tx)+_xlpm.dat-_xlpm.cpx+_xlpm.sb)-_xlpm.nw*(_xlpm.rev-_xlpm.prv),_xlpm.pv,SUM(_xlpm.f/(1+_xlpm.w)^(_xlpm.t-0.5*_xlpm.m)),_xlpm.tv,INDEX(_xlpm.f,10)*(1+_xlpm.tgr)/(_xlpm.w-_xlpm.tgr)/(1+_xlpm.w)^10,(_xlpm.pv+_xlpm.tv+_xlpm.nc)/_xlpm.shs)} | E22: {=_xlfn.LET(_xlpm.gs,DCF!$B$9,_xlpm.om,DCF!$B$10,_xlpm.w,$B22,_xlpm.tgr,E$20,_xlpm.n,DCF!$B$11,_xlpm.lcx,DCF!$B$19,_xlpm.r0,DCF!$B$37,_xlpm.om0,DCF!$B$39,_xlpm.cx0,DCF!$B$40,_xlpm.da0,DCF!$B$41,_xlpm.dar,DCF!$B$20,_xlpm.tx,DCF!$B$31,_xlpm.sb,DCF!$B$43,_xlpm.nw,DCF!$B$21,_xlpm.gd,N(DCF!$B$22),_xlpm.nc,DCF!$B$47,_xlpm.shs,DCF!$B$6,_xlpm.m,DCF!$B$48,_xlpm.t,_xlfn.SEQUENCE(10),_xlpm.g,_xlpm.gs-(_xlpm.gs-_xlpm.tgr)*(_xlpm.t-1)/9,_xlpm.cum,MMULT(--(_xlpm.t>=TRANSPOSE(_xlpm.t)),LN(1+_xlpm.g)),_xlpm.rev,_xlpm.r0*EXP(_xlpm.cum),_xlpm.prv,_xlpm.r0*EXP(_xlpm.cum-LN(1+_xlpm.g)),_xlpm.lp,IF(_xlpm.t>=_xlpm.n,1,_xlpm.t/_xlpm.n),_xlpm.omt,_xlpm.om0+(_xlpm.om-_xlpm.om0)*_xlpm.lp,_xlpm.dat,_xlpm.da0+(_xlpm.lcx*_xlpm.dar-_xlpm.da0)*_xlpm.lp,_xlpm.cpx,IF((_xlpm.t=1)*(_xlpm.gd>0),_xlpm.gd/_xlpm.rev,_xlpm.cx0+(_xlpm.lcx-_xlpm.cx0)*_xlpm.lp),_xlpm.f,_xlpm.rev*(_xlpm.omt*(1-_xlpm.tx)+_xlpm.dat-_xlpm.cpx+_xlpm.sb)-_xlpm.nw*(_xlpm.rev-_xlpm.prv),_xlpm.pv,SUM(_xlpm.f/(1+_xlpm.w)^(_xlpm.t-0.5*_xlpm.m)),_xlpm.tv,INDEX(_xlpm.f,10)*(1+_xlpm.tgr)/(_xlpm.w-_xlpm.tgr)/(1+_xlpm.w)^10,(_xlpm.pv+_xlpm.tv+_xlpm.nc)/_xlpm.shs)} | F22: {=_xlfn.LET(_xlpm.gs,DCF!$B$9,_xlpm.om,DCF!$B$10,_xlpm.w,$B22,_xlpm.tgr,F$20,_xlpm.n,DCF!$B$11,_xlpm.lcx,DCF!$B$19,_xlpm.r0,DCF!$B$37,_xlpm.om0,DCF!$B$39,_xlpm.cx0,DCF!$B$40,_xlpm.da0,DCF!$B$41,_xlpm.dar,DCF!$B$20,_xlpm.tx,DCF!$B$31,_xlpm.sb,DCF!$B$43,_xlpm.nw,DCF!$B$21,_xlpm.gd,N(DCF!$B$22),_xlpm.nc,DCF!$B$47,_xlpm.shs,DCF!$B$6,_xlpm.m,DCF!$B$48,_xlpm.t,_xlfn.SEQUENCE(10),_xlpm.g,_xlpm.gs-(_xlpm.gs-_xlpm.tgr)*(_xlpm.t-1)/9,_xlpm.cum,MMULT(--(_xlpm.t>=TRANSPOSE(_xlpm.t)),LN(1+_xlpm.g)),_xlpm.rev,_xlpm.r0*EXP(_xlpm.cum),_xlpm.prv,_xlpm.r0*EXP(_xlpm.cum-LN(1+_xlpm.g)),_xlpm.lp,IF(_xlpm.t>=_xlpm.n,1,_xlpm.t/_xlpm.n),_xlpm.omt,_xlpm.om0+(_xlpm.om-_xlpm.om0)*_xlpm.lp,_xlpm.dat,_xlpm.da0+(_xlpm.lcx*_xlpm.dar-_xlpm.da0)*_xlpm.lp,_xlpm.cpx,IF((_xlpm.t=1)*(_xlpm.gd>0),_xlpm.gd/_xlpm.rev,_xlpm.cx0+(_xlpm.lcx-_xlpm.cx0)*_xlpm.lp),_xlpm.f,_xlpm.rev*(_xlpm.omt*(1-_xlpm.tx)+_xlpm.dat-_xlpm.cpx+_xlpm.sb)-_xlpm.nw*(_xlpm.rev-_xlpm.prv),_xlpm.pv,SUM(_xlpm.f/(1+_xlpm.w)^(_xlpm.t-0.5*_xlpm.m)),_xlpm.tv,INDEX(_xlpm.f,10)*(1+_xlpm.tgr)/(_xlpm.w-_xlpm.tgr)/(1+_xlpm.w)^10,(_xlpm.pv+_xlpm.tv+_xlpm.nc)/_xlpm.shs)} | G22: {=_xlfn.LET(_xlpm.gs,DCF!$B$9,_xlpm.om,DCF!$B$10,_xlpm.w,$B22,_xlpm.tgr,G$20,_xlpm.n,DCF!$B$11,_xlpm.lcx,DCF!$B$19,_xlpm.r0,DCF!$B$37,_xlpm.om0,DCF!$B$39,_xlpm.cx0,DCF!$B$40,_xlpm.da0,DCF!$B$41,_xlpm.dar,DCF!$B$20,_xlpm.tx,DCF!$B$31,_xlpm.sb,DCF!$B$43,_xlpm.nw,DCF!$B$21,_xlpm.gd,N(DCF!$B$22),_xlpm.nc,DCF!$B$47,_xlpm.shs,DCF!$B$6,_xlpm.m,DCF!$B$48,_xlpm.t,_xlfn.SEQUENCE(10),_xlpm.g,_xlpm.gs-(_xlpm.gs-_xlpm.tgr)*(_xlpm.t-1)/9,_xlpm.cum,MMULT(--(_xlpm.t>=TRANSPOSE(_xlpm.t)),LN(1+_xlpm.g)),_xlpm.rev,_xlpm.r0*EXP(_xlpm.cum),_xlpm.prv,_xlpm.r0*EXP(_xlpm.cum-LN(1+_xlpm.g)),_xlpm.lp,IF(_xlpm.t>=_xlpm.n,1,_xlpm.t/_xlpm.n),_xlpm.omt,_xlpm.om0+(_xlpm.om-_xlpm.om0)*_xlpm.lp,_xlpm.dat,_xlpm.da0+(_xlpm.lcx*_xlpm.dar-_xlpm.da0)*_xlpm.lp,_xlpm.cpx,IF((_xlpm.t=1)*(_xlpm.gd>0),_xlpm.gd/_xlpm.rev,_xlpm.cx0+(_xlpm.lcx-_xlpm.cx0)*_xlpm.lp),_xlpm.f,_xlpm.rev*(_xlpm.omt*(1-_xlpm.tx)+_xlpm.dat-_xlpm.cpx+_xlpm.sb)-_xlpm.nw*(_xlpm.rev-_xlpm.prv),_xlpm.pv,SUM(_xlpm.f/(1+_xlpm.w)^(_xlpm.t-0.5*_xlpm.m)),_xlpm.tv,INDEX(_xlpm.f,10)*(1+_xlpm.tgr)/(_xlpm.w-_xlpm.tgr)/(1+_xlpm.w)^10,(_xlpm.pv+_xlpm.tv+_xlpm.nc)/_xlpm.shs)}
B23: =DCF!$B$7+(0) | C23: {=_xlfn.LET(_xlpm.gs,DCF!$B$9,_xlpm.om,DCF!$B$10,_xlpm.w,$B23,_xlpm.tgr,C$20,_xlpm.n,DCF!$B$11,_xlpm.lcx,DCF!$B$19,_xlpm.r0,DCF!$B$37,_xlpm.om0,DCF!$B$39,_xlpm.cx0,DCF!$B$40,_xlpm.da0,DCF!$B$41,_xlpm.dar,DCF!$B$20,_xlpm.tx,DCF!$B$31,_xlpm.sb,DCF!$B$43,_xlpm.nw,DCF!$B$21,_xlpm.gd,N(DCF!$B$22),_xlpm.nc,DCF!$B$47,_xlpm.shs,DCF!$B$6,_xlpm.m,DCF!$B$48,_xlpm.t,_xlfn.SEQUENCE(10),_xlpm.g,_xlpm.gs-(_xlpm.gs-_xlpm.tgr)*(_xlpm.t-1)/9,_xlpm.cum,MMULT(--(_xlpm.t>=TRANSPOSE(_xlpm.t)),LN(1+_xlpm.g)),_xlpm.rev,_xlpm.r0*EXP(_xlpm.cum),_xlpm.prv,_xlpm.r0*EXP(_xlpm.cum-LN(1+_xlpm.g)),_xlpm.lp,IF(_xlpm.t>=_xlpm.n,1,_xlpm.t/_xlpm.n),_xlpm.omt,_xlpm.om0+(_xlpm.om-_xlpm.om0)*_xlpm.lp,_xlpm.dat,_xlpm.da0+(_xlpm.lcx*_xlpm.dar-_xlpm.da0)*_xlpm.lp,_xlpm.cpx,IF((_xlpm.t=1)*(_xlpm.gd>0),_xlpm.gd/_xlpm.rev,_xlpm.cx0+(_xlpm.lcx-_xlpm.cx0)*_xlpm.lp),_xlpm.f,_xlpm.rev*(_xlpm.omt*(1-_xlpm.tx)+_xlpm.dat-_xlpm.cpx+_xlpm.sb)-_xlpm.nw*(_xlpm.rev-_xlpm.prv),_xlpm.pv,SUM(_xlpm.f/(1+_xlpm.w)^(_xlpm.t-0.5*_xlpm.m)),_xlpm.tv,INDEX(_xlpm.f,10)*(1+_xlpm.tgr)/(_xlpm.w-_xlpm.tgr)/(1+_xlpm.w)^10,(_xlpm.pv+_xlpm.tv+_xlpm.nc)/_xlpm.shs)} | D23: {=_xlfn.LET(_xlpm.gs,DCF!$B$9,_xlpm.om,DCF!$B$10,_xlpm.w,$B23,_xlpm.tgr,D$20,_xlpm.n,DCF!$B$11,_xlpm.lcx,DCF!$B$19,_xlpm.r0,DCF!$B$37,_xlpm.om0,DCF!$B$39,_xlpm.cx0,DCF!$B$40,_xlpm.da0,DCF!$B$41,_xlpm.dar,DCF!$B$20,_xlpm.tx,DCF!$B$31,_xlpm.sb,DCF!$B$43,_xlpm.nw,DCF!$B$21,_xlpm.gd,N(DCF!$B$22),_xlpm.nc,DCF!$B$47,_xlpm.shs,DCF!$B$6,_xlpm.m,DCF!$B$48,_xlpm.t,_xlfn.SEQUENCE(10),_xlpm.g,_xlpm.gs-(_xlpm.gs-_xlpm.tgr)*(_xlpm.t-1)/9,_xlpm.cum,MMULT(--(_xlpm.t>=TRANSPOSE(_xlpm.t)),LN(1+_xlpm.g)),_xlpm.rev,_xlpm.r0*EXP(_xlpm.cum),_xlpm.prv,_xlpm.r0*EXP(_xlpm.cum-LN(1+_xlpm.g)),_xlpm.lp,IF(_xlpm.t>=_xlpm.n,1,_xlpm.t/_xlpm.n),_xlpm.omt,_xlpm.om0+(_xlpm.om-_xlpm.om0)*_xlpm.lp,_xlpm.dat,_xlpm.da0+(_xlpm.lcx*_xlpm.dar-_xlpm.da0)*_xlpm.lp,_xlpm.cpx,IF((_xlpm.t=1)*(_xlpm.gd>0),_xlpm.gd/_xlpm.rev,_xlpm.cx0+(_xlpm.lcx-_xlpm.cx0)*_xlpm.lp),_xlpm.f,_xlpm.rev*(_xlpm.omt*(1-_xlpm.tx)+_xlpm.dat-_xlpm.cpx+_xlpm.sb)-_xlpm.nw*(_xlpm.rev-_xlpm.prv),_xlpm.pv,SUM(_xlpm.f/(1+_xlpm.w)^(_xlpm.t-0.5*_xlpm.m)),_xlpm.tv,INDEX(_xlpm.f,10)*(1+_xlpm.tgr)/(_xlpm.w-_xlpm.tgr)/(1+_xlpm.w)^10,(_xlpm.pv+_xlpm.tv+_xlpm.nc)/_xlpm.shs)} | E23: {=_xlfn.LET(_xlpm.gs,DCF!$B$9,_xlpm.om,DCF!$B$10,_xlpm.w,$B23,_xlpm.tgr,E$20,_xlpm.n,DCF!$B$11,_xlpm.lcx,DCF!$B$19,_xlpm.r0,DCF!$B$37,_xlpm.om0,DCF!$B$39,_xlpm.cx0,DCF!$B$40,_xlpm.da0,DCF!$B$41,_xlpm.dar,DCF!$B$20,_xlpm.tx,DCF!$B$31,_xlpm.sb,DCF!$B$43,_xlpm.nw,DCF!$B$21,_xlpm.gd,N(DCF!$B$22),_xlpm.nc,DCF!$B$47,_xlpm.shs,DCF!$B$6,_xlpm.m,DCF!$B$48,_xlpm.t,_xlfn.SEQUENCE(10),_xlpm.g,_xlpm.gs-(_xlpm.gs-_xlpm.tgr)*(_xlpm.t-1)/9,_xlpm.cum,MMULT(--(_xlpm.t>=TRANSPOSE(_xlpm.t)),LN(1+_xlpm.g)),_xlpm.rev,_xlpm.r0*EXP(_xlpm.cum),_xlpm.prv,_xlpm.r0*EXP(_xlpm.cum-LN(1+_xlpm.g)),_xlpm.lp,IF(_xlpm.t>=_xlpm.n,1,_xlpm.t/_xlpm.n),_xlpm.omt,_xlpm.om0+(_xlpm.om-_xlpm.om0)*_xlpm.lp,_xlpm.dat,_xlpm.da0+(_xlpm.lcx*_xlpm.dar-_xlpm.da0)*_xlpm.lp,_xlpm.cpx,IF((_xlpm.t=1)*(_xlpm.gd>0),_xlpm.gd/_xlpm.rev,_xlpm.cx0+(_xlpm.lcx-_xlpm.cx0)*_xlpm.lp),_xlpm.f,_xlpm.rev*(_xlpm.omt*(1-_xlpm.tx)+_xlpm.dat-_xlpm.cpx+_xlpm.sb)-_xlpm.nw*(_xlpm.rev-_xlpm.prv),_xlpm.pv,SUM(_xlpm.f/(1+_xlpm.w)^(_xlpm.t-0.5*_xlpm.m)),_xlpm.tv,INDEX(_xlpm.f,10)*(1+_xlpm.tgr)/(_xlpm.w-_xlpm.tgr)/(1+_xlpm.w)^10,(_xlpm.pv+_xlpm.tv+_xlpm.nc)/_xlpm.shs)} | F23: {=_xlfn.LET(_xlpm.gs,DCF!$B$9,_xlpm.om,DCF!$B$10,_xlpm.w,$B23,_xlpm.tgr,F$20,_xlpm.n,DCF!$B$11,_xlpm.lcx,DCF!$B$19,_xlpm.r0,DCF!$B$37,_xlpm.om0,DCF!$B$39,_xlpm.cx0,DCF!$B$40,_xlpm.da0,DCF!$B$41,_xlpm.dar,DCF!$B$20,_xlpm.tx,DCF!$B$31,_xlpm.sb,DCF!$B$43,_xlpm.nw,DCF!$B$21,_xlpm.gd,N(DCF!$B$22),_xlpm.nc,DCF!$B$47,_xlpm.shs,DCF!$B$6,_xlpm.m,DCF!$B$48,_xlpm.t,_xlfn.SEQUENCE(10),_xlpm.g,_xlpm.gs-(_xlpm.gs-_xlpm.tgr)*(_xlpm.t-1)/9,_xlpm.cum,MMULT(--(_xlpm.t>=TRANSPOSE(_xlpm.t)),LN(1+_xlpm.g)),_xlpm.rev,_xlpm.r0*EXP(_xlpm.cum),_xlpm.prv,_xlpm.r0*EXP(_xlpm.cum-LN(1+_xlpm.g)),_xlpm.lp,IF(_xlpm.t>=_xlpm.n,1,_xlpm.t/_xlpm.n),_xlpm.omt,_xlpm.om0+(_xlpm.om-_xlpm.om0)*_xlpm.lp,_xlpm.dat,_xlpm.da0+(_xlpm.lcx*_xlpm.dar-_xlpm.da0)*_xlpm.lp,_xlpm.cpx,IF((_xlpm.t=1)*(_xlpm.gd>0),_xlpm.gd/_xlpm.rev,_xlpm.cx0+(_xlpm.lcx-_xlpm.cx0)*_xlpm.lp),_xlpm.f,_xlpm.rev*(_xlpm.omt*(1-_xlpm.tx)+_xlpm.dat-_xlpm.cpx+_xlpm.sb)-_xlpm.nw*(_xlpm.rev-_xlpm.prv),_xlpm.pv,SUM(_xlpm.f/(1+_xlpm.w)^(_xlpm.t-0.5*_xlpm.m)),_xlpm.tv,INDEX(_xlpm.f,10)*(1+_xlpm.tgr)/(_xlpm.w-_xlpm.tgr)/(1+_xlpm.w)^10,(_xlpm.pv+_xlpm.tv+_xlpm.nc)/_xlpm.shs)} | G23: {=_xlfn.LET(_xlpm.gs,DCF!$B$9,_xlpm.om,DCF!$B$10,_xlpm.w,$B23,_xlpm.tgr,G$20,_xlpm.n,DCF!$B$11,_xlpm.lcx,DCF!$B$19,_xlpm.r0,DCF!$B$37,_xlpm.om0,DCF!$B$39,_xlpm.cx0,DCF!$B$40,_xlpm.da0,DCF!$B$41,_xlpm.dar,DCF!$B$20,_xlpm.tx,DCF!$B$31,_xlpm.sb,DCF!$B$43,_xlpm.nw,DCF!$B$21,_xlpm.gd,N(DCF!$B$22),_xlpm.nc,DCF!$B$47,_xlpm.shs,DCF!$B$6,_xlpm.m,DCF!$B$48,_xlpm.t,_xlfn.SEQUENCE(10),_xlpm.g,_xlpm.gs-(_xlpm.gs-_xlpm.tgr)*(_xlpm.t-1)/9,_xlpm.cum,MMULT(--(_xlpm.t>=TRANSPOSE(_xlpm.t)),LN(1+_xlpm.g)),_xlpm.rev,_xlpm.r0*EXP(_xlpm.cum),_xlpm.prv,_xlpm.r0*EXP(_xlpm.cum-LN(1+_xlpm.g)),_xlpm.lp,IF(_xlpm.t>=_xlpm.n,1,_xlpm.t/_xlpm.n),_xlpm.omt,_xlpm.om0+(_xlpm.om-_xlpm.om0)*_xlpm.lp,_xlpm.dat,_xlpm.da0+(_xlpm.lcx*_xlpm.dar-_xlpm.da0)*_xlpm.lp,_xlpm.cpx,IF((_xlpm.t=1)*(_xlpm.gd>0),_xlpm.gd/_xlpm.rev,_xlpm.cx0+(_xlpm.lcx-_xlpm.cx0)*_xlpm.lp),_xlpm.f,_xlpm.rev*(_xlpm.omt*(1-_xlpm.tx)+_xlpm.dat-_xlpm.cpx+_xlpm.sb)-_xlpm.nw*(_xlpm.rev-_xlpm.prv),_xlpm.pv,SUM(_xlpm.f/(1+_xlpm.w)^(_xlpm.t-0.5*_xlpm.m)),_xlpm.tv,INDEX(_xlpm.f,10)*(1+_xlpm.tgr)/(_xlpm.w-_xlpm.tgr)/(1+_xlpm.w)^10,(_xlpm.pv+_xlpm.tv+_xlpm.nc)/_xlpm.shs)}
B24: =DCF!$B$7+(0.005) | C24: {=_xlfn.LET(_xlpm.gs,DCF!$B$9,_xlpm.om,DCF!$B$10,_xlpm.w,$B24,_xlpm.tgr,C$20,_xlpm.n,DCF!$B$11,_xlpm.lcx,DCF!$B$19,_xlpm.r0,DCF!$B$37,_xlpm.om0,DCF!$B$39,_xlpm.cx0,DCF!$B$40,_xlpm.da0,DCF!$B$41,_xlpm.dar,DCF!$B$20,_xlpm.tx,DCF!$B$31,_xlpm.sb,DCF!$B$43,_xlpm.nw,DCF!$B$21,_xlpm.gd,N(DCF!$B$22),_xlpm.nc,DCF!$B$47,_xlpm.shs,DCF!$B$6,_xlpm.m,DCF!$B$48,_xlpm.t,_xlfn.SEQUENCE(10),_xlpm.g,_xlpm.gs-(_xlpm.gs-_xlpm.tgr)*(_xlpm.t-1)/9,_xlpm.cum,MMULT(--(_xlpm.t>=TRANSPOSE(_xlpm.t)),LN(1+_xlpm.g)),_xlpm.rev,_xlpm.r0*EXP(_xlpm.cum),_xlpm.prv,_xlpm.r0*EXP(_xlpm.cum-LN(1+_xlpm.g)),_xlpm.lp,IF(_xlpm.t>=_xlpm.n,1,_xlpm.t/_xlpm.n),_xlpm.omt,_xlpm.om0+(_xlpm.om-_xlpm.om0)*_xlpm.lp,_xlpm.dat,_xlpm.da0+(_xlpm.lcx*_xlpm.dar-_xlpm.da0)*_xlpm.lp,_xlpm.cpx,IF((_xlpm.t=1)*(_xlpm.gd>0),_xlpm.gd/_xlpm.rev,_xlpm.cx0+(_xlpm.lcx-_xlpm.cx0)*_xlpm.lp),_xlpm.f,_xlpm.rev*(_xlpm.omt*(1-_xlpm.tx)+_xlpm.dat-_xlpm.cpx+_xlpm.sb)-_xlpm.nw*(_xlpm.rev-_xlpm.prv),_xlpm.pv,SUM(_xlpm.f/(1+_xlpm.w)^(_xlpm.t-0.5*_xlpm.m)),_xlpm.tv,INDEX(_xlpm.f,10)*(1+_xlpm.tgr)/(_xlpm.w-_xlpm.tgr)/(1+_xlpm.w)^10,(_xlpm.pv+_xlpm.tv+_xlpm.nc)/_xlpm.shs)} | D24: {=_xlfn.LET(_xlpm.gs,DCF!$B$9,_xlpm.om,DCF!$B$10,_xlpm.w,$B24,_xlpm.tgr,D$20,_xlpm.n,DCF!$B$11,_xlpm.lcx,DCF!$B$19,_xlpm.r0,DCF!$B$37,_xlpm.om0,DCF!$B$39,_xlpm.cx0,DCF!$B$40,_xlpm.da0,DCF!$B$41,_xlpm.dar,DCF!$B$20,_xlpm.tx,DCF!$B$31,_xlpm.sb,DCF!$B$43,_xlpm.nw,DCF!$B$21,_xlpm.gd,N(DCF!$B$22),_xlpm.nc,DCF!$B$47,_xlpm.shs,DCF!$B$6,_xlpm.m,DCF!$B$48,_xlpm.t,_xlfn.SEQUENCE(10),_xlpm.g,_xlpm.gs-(_xlpm.gs-_xlpm.tgr)*(_xlpm.t-1)/9,_xlpm.cum,MMULT(--(_xlpm.t>=TRANSPOSE(_xlpm.t)),LN(1+_xlpm.g)),_xlpm.rev,_xlpm.r0*EXP(_xlpm.cum),_xlpm.prv,_xlpm.r0*EXP(_xlpm.cum-LN(1+_xlpm.g)),_xlpm.lp,IF(_xlpm.t>=_xlpm.n,1,_xlpm.t/_xlpm.n),_xlpm.omt,_xlpm.om0+(_xlpm.om-_xlpm.om0)*_xlpm.lp,_xlpm.dat,_xlpm.da0+(_xlpm.lcx*_xlpm.dar-_xlpm.da0)*_xlpm.lp,_xlpm.cpx,IF((_xlpm.t=1)*(_xlpm.gd>0),_xlpm.gd/_xlpm.rev,_xlpm.cx0+(_xlpm.lcx-_xlpm.cx0)*_xlpm.lp),_xlpm.f,_xlpm.rev*(_xlpm.omt*(1-_xlpm.tx)+_xlpm.dat-_xlpm.cpx+_xlpm.sb)-_xlpm.nw*(_xlpm.rev-_xlpm.prv),_xlpm.pv,SUM(_xlpm.f/(1+_xlpm.w)^(_xlpm.t-0.5*_xlpm.m)),_xlpm.tv,INDEX(_xlpm.f,10)*(1+_xlpm.tgr)/(_xlpm.w-_xlpm.tgr)/(1+_xlpm.w)^10,(_xlpm.pv+_xlpm.tv+_xlpm.nc)/_xlpm.shs)} | E24: {=_xlfn.LET(_xlpm.gs,DCF!$B$9,_xlpm.om,DCF!$B$10,_xlpm.w,$B24,_xlpm.tgr,E$20,_xlpm.n,DCF!$B$11,_xlpm.lcx,DCF!$B$19,_xlpm.r0,DCF!$B$37,_xlpm.om0,DCF!$B$39,_xlpm.cx0,DCF!$B$40,_xlpm.da0,DCF!$B$41,_xlpm.dar,DCF!$B$20,_xlpm.tx,DCF!$B$31,_xlpm.sb,DCF!$B$43,_xlpm.nw,DCF!$B$21,_xlpm.gd,N(DCF!$B$22),_xlpm.nc,DCF!$B$47,_xlpm.shs,DCF!$B$6,_xlpm.m,DCF!$B$48,_xlpm.t,_xlfn.SEQUENCE(10),_xlpm.g,_xlpm.gs-(_xlpm.gs-_xlpm.tgr)*(_xlpm.t-1)/9,_xlpm.cum,MMULT(--(_xlpm.t>=TRANSPOSE(_xlpm.t)),LN(1+_xlpm.g)),_xlpm.rev,_xlpm.r0*EXP(_xlpm.cum),_xlpm.prv,_xlpm.r0*EXP(_xlpm.cum-LN(1+_xlpm.g)),_xlpm.lp,IF(_xlpm.t>=_xlpm.n,1,_xlpm.t/_xlpm.n),_xlpm.omt,_xlpm.om0+(_xlpm.om-_xlpm.om0)*_xlpm.lp,_xlpm.dat,_xlpm.da0+(_xlpm.lcx*_xlpm.dar-_xlpm.da0)*_xlpm.lp,_xlpm.cpx,IF((_xlpm.t=1)*(_xlpm.gd>0),_xlpm.gd/_xlpm.rev,_xlpm.cx0+(_xlpm.lcx-_xlpm.cx0)*_xlpm.lp),_xlpm.f,_xlpm.rev*(_xlpm.omt*(1-_xlpm.tx)+_xlpm.dat-_xlpm.cpx+_xlpm.sb)-_xlpm.nw*(_xlpm.rev-_xlpm.prv),_xlpm.pv,SUM(_xlpm.f/(1+_xlpm.w)^(_xlpm.t-0.5*_xlpm.m)),_xlpm.tv,INDEX(_xlpm.f,10)*(1+_xlpm.tgr)/(_xlpm.w-_xlpm.tgr)/(1+_xlpm.w)^10,(_xlpm.pv+_xlpm.tv+_xlpm.nc)/_xlpm.shs)} | F24: {=_xlfn.LET(_xlpm.gs,DCF!$B$9,_xlpm.om,DCF!$B$10,_xlpm.w,$B24,_xlpm.tgr,F$20,_xlpm.n,DCF!$B$11,_xlpm.lcx,DCF!$B$19,_xlpm.r0,DCF!$B$37,_xlpm.om0,DCF!$B$39,_xlpm.cx0,DCF!$B$40,_xlpm.da0,DCF!$B$41,_xlpm.dar,DCF!$B$20,_xlpm.tx,DCF!$B$31,_xlpm.sb,DCF!$B$43,_xlpm.nw,DCF!$B$21,_xlpm.gd,N(DCF!$B$22),_xlpm.nc,DCF!$B$47,_xlpm.shs,DCF!$B$6,_xlpm.m,DCF!$B$48,_xlpm.t,_xlfn.SEQUENCE(10),_xlpm.g,_xlpm.gs-(_xlpm.gs-_xlpm.tgr)*(_xlpm.t-1)/9,_xlpm.cum,MMULT(--(_xlpm.t>=TRANSPOSE(_xlpm.t)),LN(1+_xlpm.g)),_xlpm.rev,_xlpm.r0*EXP(_xlpm.cum),_xlpm.prv,_xlpm.r0*EXP(_xlpm.cum-LN(1+_xlpm.g)),_xlpm.lp,IF(_xlpm.t>=_xlpm.n,1,_xlpm.t/_xlpm.n),_xlpm.omt,_xlpm.om0+(_xlpm.om-_xlpm.om0)*_xlpm.lp,_xlpm.dat,_xlpm.da0+(_xlpm.lcx*_xlpm.dar-_xlpm.da0)*_xlpm.lp,_xlpm.cpx,IF((_xlpm.t=1)*(_xlpm.gd>0),_xlpm.gd/_xlpm.rev,_xlpm.cx0+(_xlpm.lcx-_xlpm.cx0)*_xlpm.lp),_xlpm.f,_xlpm.rev*(_xlpm.omt*(1-_xlpm.tx)+_xlpm.dat-_xlpm.cpx+_xlpm.sb)-_xlpm.nw*(_xlpm.rev-_xlpm.prv),_xlpm.pv,SUM(_xlpm.f/(1+_xlpm.w)^(_xlpm.t-0.5*_xlpm.m)),_xlpm.tv,INDEX(_xlpm.f,10)*(1+_xlpm.tgr)/(_xlpm.w-_xlpm.tgr)/(1+_xlpm.w)^10,(_xlpm.pv+_xlpm.tv+_xlpm.nc)/_xlpm.shs)} | G24: {=_xlfn.LET(_xlpm.gs,DCF!$B$9,_xlpm.om,DCF!$B$10,_xlpm.w,$B24,_xlpm.tgr,G$20,_xlpm.n,DCF!$B$11,_xlpm.lcx,DCF!$B$19,_xlpm.r0,DCF!$B$37,_xlpm.om0,DCF!$B$39,_xlpm.cx0,DCF!$B$40,_xlpm.da0,DCF!$B$41,_xlpm.dar,DCF!$B$20,_xlpm.tx,DCF!$B$31,_xlpm.sb,DCF!$B$43,_xlpm.nw,DCF!$B$21,_xlpm.gd,N(DCF!$B$22),_xlpm.nc,DCF!$B$47,_xlpm.shs,DCF!$B$6,_xlpm.m,DCF!$B$48,_xlpm.t,_xlfn.SEQUENCE(10),_xlpm.g,_xlpm.gs-(_xlpm.gs-_xlpm.tgr)*(_xlpm.t-1)/9,_xlpm.cum,MMULT(--(_xlpm.t>=TRANSPOSE(_xlpm.t)),LN(1+_xlpm.g)),_xlpm.rev,_xlpm.r0*EXP(_xlpm.cum),_xlpm.prv,_xlpm.r0*EXP(_xlpm.cum-LN(1+_xlpm.g)),_xlpm.lp,IF(_xlpm.t>=_xlpm.n,1,_xlpm.t/_xlpm.n),_xlpm.omt,_xlpm.om0+(_xlpm.om-_xlpm.om0)*_xlpm.lp,_xlpm.dat,_xlpm.da0+(_xlpm.lcx*_xlpm.dar-_xlpm.da0)*_xlpm.lp,_xlpm.cpx,IF((_xlpm.t=1)*(_xlpm.gd>0),_xlpm.gd/_xlpm.rev,_xlpm.cx0+(_xlpm.lcx-_xlpm.cx0)*_xlpm.lp),_xlpm.f,_xlpm.rev*(_xlpm.omt*(1-_xlpm.tx)+_xlpm.dat-_xlpm.cpx+_xlpm.sb)-_xlpm.nw*(_xlpm.rev-_xlpm.prv),_xlpm.pv,SUM(_xlpm.f/(1+_xlpm.w)^(_xlpm.t-0.5*_xlpm.m)),_xlpm.tv,INDEX(_xlpm.f,10)*(1+_xlpm.tgr)/(_xlpm.w-_xlpm.tgr)/(1+_xlpm.w)^10,(_xlpm.pv+_xlpm.tv+_xlpm.nc)/_xlpm.shs)}
B25: =DCF!$B$7+(0.01) | C25: {=_xlfn.LET(_xlpm.gs,DCF!$B$9,_xlpm.om,DCF!$B$10,_xlpm.w,$B25,_xlpm.tgr,C$20,_xlpm.n,DCF!$B$11,_xlpm.lcx,DCF!$B$19,_xlpm.r0,DCF!$B$37,_xlpm.om0,DCF!$B$39,_xlpm.cx0,DCF!$B$40,_xlpm.da0,DCF!$B$41,_xlpm.dar,DCF!$B$20,_xlpm.tx,DCF!$B$31,_xlpm.sb,DCF!$B$43,_xlpm.nw,DCF!$B$21,_xlpm.gd,N(DCF!$B$22),_xlpm.nc,DCF!$B$47,_xlpm.shs,DCF!$B$6,_xlpm.m,DCF!$B$48,_xlpm.t,_xlfn.SEQUENCE(10),_xlpm.g,_xlpm.gs-(_xlpm.gs-_xlpm.tgr)*(_xlpm.t-1)/9,_xlpm.cum,MMULT(--(_xlpm.t>=TRANSPOSE(_xlpm.t)),LN(1+_xlpm.g)),_xlpm.rev,_xlpm.r0*EXP(_xlpm.cum),_xlpm.prv,_xlpm.r0*EXP(_xlpm.cum-LN(1+_xlpm.g)),_xlpm.lp,IF(_xlpm.t>=_xlpm.n,1,_xlpm.t/_xlpm.n),_xlpm.omt,_xlpm.om0+(_xlpm.om-_xlpm.om0)*_xlpm.lp,_xlpm.dat,_xlpm.da0+(_xlpm.lcx*_xlpm.dar-_xlpm.da0)*_xlpm.lp,_xlpm.cpx,IF((_xlpm.t=1)*(_xlpm.gd>0),_xlpm.gd/_xlpm.rev,_xlpm.cx0+(_xlpm.lcx-_xlpm.cx0)*_xlpm.lp),_xlpm.f,_xlpm.rev*(_xlpm.omt*(1-_xlpm.tx)+_xlpm.dat-_xlpm.cpx+_xlpm.sb)-_xlpm.nw*(_xlpm.rev-_xlpm.prv),_xlpm.pv,SUM(_xlpm.f/(1+_xlpm.w)^(_xlpm.t-0.5*_xlpm.m)),_xlpm.tv,INDEX(_xlpm.f,10)*(1+_xlpm.tgr)/(_xlpm.w-_xlpm.tgr)/(1+_xlpm.w)^10,(_xlpm.pv+_xlpm.tv+_xlpm.nc)/_xlpm.shs)} | D25: {=_xlfn.LET(_xlpm.gs,DCF!$B$9,_xlpm.om,DCF!$B$10,_xlpm.w,$B25,_xlpm.tgr,D$20,_xlpm.n,DCF!$B$11,_xlpm.lcx,DCF!$B$19,_xlpm.r0,DCF!$B$37,_xlpm.om0,DCF!$B$39,_xlpm.cx0,DCF!$B$40,_xlpm.da0,DCF!$B$41,_xlpm.dar,DCF!$B$20,_xlpm.tx,DCF!$B$31,_xlpm.sb,DCF!$B$43,_xlpm.nw,DCF!$B$21,_xlpm.gd,N(DCF!$B$22),_xlpm.nc,DCF!$B$47,_xlpm.shs,DCF!$B$6,_xlpm.m,DCF!$B$48,_xlpm.t,_xlfn.SEQUENCE(10),_xlpm.g,_xlpm.gs-(_xlpm.gs-_xlpm.tgr)*(_xlpm.t-1)/9,_xlpm.cum,MMULT(--(_xlpm.t>=TRANSPOSE(_xlpm.t)),LN(1+_xlpm.g)),_xlpm.rev,_xlpm.r0*EXP(_xlpm.cum),_xlpm.prv,_xlpm.r0*EXP(_xlpm.cum-LN(1+_xlpm.g)),_xlpm.lp,IF(_xlpm.t>=_xlpm.n,1,_xlpm.t/_xlpm.n),_xlpm.omt,_xlpm.om0+(_xlpm.om-_xlpm.om0)*_xlpm.lp,_xlpm.dat,_xlpm.da0+(_xlpm.lcx*_xlpm.dar-_xlpm.da0)*_xlpm.lp,_xlpm.cpx,IF((_xlpm.t=1)*(_xlpm.gd>0),_xlpm.gd/_xlpm.rev,_xlpm.cx0+(_xlpm.lcx-_xlpm.cx0)*_xlpm.lp),_xlpm.f,_xlpm.rev*(_xlpm.omt*(1-_xlpm.tx)+_xlpm.dat-_xlpm.cpx+_xlpm.sb)-_xlpm.nw*(_xlpm.rev-_xlpm.prv),_xlpm.pv,SUM(_xlpm.f/(1+_xlpm.w)^(_xlpm.t-0.5*_xlpm.m)),_xlpm.tv,INDEX(_xlpm.f,10)*(1+_xlpm.tgr)/(_xlpm.w-_xlpm.tgr)/(1+_xlpm.w)^10,(_xlpm.pv+_xlpm.tv+_xlpm.nc)/_xlpm.shs)} | E25: {=_xlfn.LET(_xlpm.gs,DCF!$B$9,_xlpm.om,DCF!$B$10,_xlpm.w,$B25,_xlpm.tgr,E$20,_xlpm.n,DCF!$B$11,_xlpm.lcx,DCF!$B$19,_xlpm.r0,DCF!$B$37,_xlpm.om0,DCF!$B$39,_xlpm.cx0,DCF!$B$40,_xlpm.da0,DCF!$B$41,_xlpm.dar,DCF!$B$20,_xlpm.tx,DCF!$B$31,_xlpm.sb,DCF!$B$43,_xlpm.nw,DCF!$B$21,_xlpm.gd,N(DCF!$B$22),_xlpm.nc,DCF!$B$47,_xlpm.shs,DCF!$B$6,_xlpm.m,DCF!$B$48,_xlpm.t,_xlfn.SEQUENCE(10),_xlpm.g,_xlpm.gs-(_xlpm.gs-_xlpm.tgr)*(_xlpm.t-1)/9,_xlpm.cum,MMULT(--(_xlpm.t>=TRANSPOSE(_xlpm.t)),LN(1+_xlpm.g)),_xlpm.rev,_xlpm.r0*EXP(_xlpm.cum),_xlpm.prv,_xlpm.r0*EXP(_xlpm.cum-LN(1+_xlpm.g)),_xlpm.lp,IF(_xlpm.t>=_xlpm.n,1,_xlpm.t/_xlpm.n),_xlpm.omt,_xlpm.om0+(_xlpm.om-_xlpm.om0)*_xlpm.lp,_xlpm.dat,_xlpm.da0+(_xlpm.lcx*_xlpm.dar-_xlpm.da0)*_xlpm.lp,_xlpm.cpx,IF((_xlpm.t=1)*(_xlpm.gd>0),_xlpm.gd/_xlpm.rev,_xlpm.cx0+(_xlpm.lcx-_xlpm.cx0)*_xlpm.lp),_xlpm.f,_xlpm.rev*(_xlpm.omt*(1-_xlpm.tx)+_xlpm.dat-_xlpm.cpx+_xlpm.sb)-_xlpm.nw*(_xlpm.rev-_xlpm.prv),_xlpm.pv,SUM(_xlpm.f/(1+_xlpm.w)^(_xlpm.t-0.5*_xlpm.m)),_xlpm.tv,INDEX(_xlpm.f,10)*(1+_xlpm.tgr)/(_xlpm.w-_xlpm.tgr)/(1+_xlpm.w)^10,(_xlpm.pv+_xlpm.tv+_xlpm.nc)/_xlpm.shs)} | F25: {=_xlfn.LET(_xlpm.gs,DCF!$B$9,_xlpm.om,DCF!$B$10,_xlpm.w,$B25,_xlpm.tgr,F$20,_xlpm.n,DCF!$B$11,_xlpm.lcx,DCF!$B$19,_xlpm.r0,DCF!$B$37,_xlpm.om0,DCF!$B$39,_xlpm.cx0,DCF!$B$40,_xlpm.da0,DCF!$B$41,_xlpm.dar,DCF!$B$20,_xlpm.tx,DCF!$B$31,_xlpm.sb,DCF!$B$43,_xlpm.nw,DCF!$B$21,_xlpm.gd,N(DCF!$B$22),_xlpm.nc,DCF!$B$47,_xlpm.shs,DCF!$B$6,_xlpm.m,DCF!$B$48,_xlpm.t,_xlfn.SEQUENCE(10),_xlpm.g,_xlpm.gs-(_xlpm.gs-_xlpm.tgr)*(_xlpm.t-1)/9,_xlpm.cum,MMULT(--(_xlpm.t>=TRANSPOSE(_xlpm.t)),LN(1+_xlpm.g)),_xlpm.rev,_xlpm.r0*EXP(_xlpm.cum),_xlpm.prv,_xlpm.r0*EXP(_xlpm.cum-LN(1+_xlpm.g)),_xlpm.lp,IF(_xlpm.t>=_xlpm.n,1,_xlpm.t/_xlpm.n),_xlpm.omt,_xlpm.om0+(_xlpm.om-_xlpm.om0)*_xlpm.lp,_xlpm.dat,_xlpm.da0+(_xlpm.lcx*_xlpm.dar-_xlpm.da0)*_xlpm.lp,_xlpm.cpx,IF((_xlpm.t=1)*(_xlpm.gd>0),_xlpm.gd/_xlpm.rev,_xlpm.cx0+(_xlpm.lcx-_xlpm.cx0)*_xlpm.lp),_xlpm.f,_xlpm.rev*(_xlpm.omt*(1-_xlpm.tx)+_xlpm.dat-_xlpm.cpx+_xlpm.sb)-_xlpm.nw*(_xlpm.rev-_xlpm.prv),_xlpm.pv,SUM(_xlpm.f/(1+_xlpm.w)^(_xlpm.t-0.5*_xlpm.m)),_xlpm.tv,INDEX(_xlpm.f,10)*(1+_xlpm.tgr)/(_xlpm.w-_xlpm.tgr)/(1+_xlpm.w)^10,(_xlpm.pv+_xlpm.tv+_xlpm.nc)/_xlpm.shs)} | G25: {=_xlfn.LET(_xlpm.gs,DCF!$B$9,_xlpm.om,DCF!$B$10,_xlpm.w,$B25,_xlpm.tgr,G$20,_xlpm.n,DCF!$B$11,_xlpm.lcx,DCF!$B$19,_xlpm.r0,DCF!$B$37,_xlpm.om0,DCF!$B$39,_xlpm.cx0,DCF!$B$40,_xlpm.da0,DCF!$B$41,_xlpm.dar,DCF!$B$20,_xlpm.tx,DCF!$B$31,_xlpm.sb,DCF!$B$43,_xlpm.nw,DCF!$B$21,_xlpm.gd,N(DCF!$B$22),_xlpm.nc,DCF!$B$47,_xlpm.shs,DCF!$B$6,_xlpm.m,DCF!$B$48,_xlpm.t,_xlfn.SEQUENCE(10),_xlpm.g,_xlpm.gs-(_xlpm.gs-_xlpm.tgr)*(_xlpm.t-1)/9,_xlpm.cum,MMULT(--(_xlpm.t>=TRANSPOSE(_xlpm.t)),LN(1+_xlpm.g)),_xlpm.rev,_xlpm.r0*EXP(_xlpm.cum),_xlpm.prv,_xlpm.r0*EXP(_xlpm.cum-LN(1+_xlpm.g)),_xlpm.lp,IF(_xlpm.t>=_xlpm.n,1,_xlpm.t/_xlpm.n),_xlpm.omt,_xlpm.om0+(_xlpm.om-_xlpm.om0)*_xlpm.lp,_xlpm.dat,_xlpm.da0+(_xlpm.lcx*_xlpm.dar-_xlpm.da0)*_xlpm.lp,_xlpm.cpx,IF((_xlpm.t=1)*(_xlpm.gd>0),_xlpm.gd/_xlpm.rev,_xlpm.cx0+(_xlpm.lcx-_xlpm.cx0)*_xlpm.lp),_xlpm.f,_xlpm.rev*(_xlpm.omt*(1-_xlpm.tx)+_xlpm.dat-_xlpm.cpx+_xlpm.sb)-_xlpm.nw*(_xlpm.rev-_xlpm.prv),_xlpm.pv,SUM(_xlpm.f/(1+_xlpm.w)^(_xlpm.t-0.5*_xlpm.m)),_xlpm.tv,INDEX(_xlpm.f,10)*(1+_xlpm.tgr)/(_xlpm.w-_xlpm.tgr)/(1+_xlpm.w)^10,(_xlpm.pv+_xlpm.tv+_xlpm.nc)/_xlpm.shs)}
A27: Sensitivity 2 — fair value per share: year-1 revenue growth (rows) × long-run operating margin (columns) | I27: Sensitivity 3 — long-run capex % of revenue (rows) × years to normalise (columns)
B28: Growth ↓ · margin → | C28: =DCF!$B$10+(-0.04) | D28: =DCF!$B$10+(-0.02) | E28: =DCF!$B$10+(0) | F28: =DCF!$B$10+(0.02) | G28: =DCF!$B$10+(0.04) | J28: Capex ↓ · years → | K28: =MAX(1,DCF!$B$11-2) | L28: =MAX(1,DCF!$B$11-1) | M28: =DCF!$B$11 | N28: =DCF!$B$11+1 | O28: =DCF!$B$11+2
B29: =DCF!$B$9+(-0.06) | C29: {=_xlfn.LET(_xlpm.gs,$B29,_xlpm.om,C$28,_xlpm.w,DCF!$B$7,_xlpm.tgr,DCF!$B$8,_xlpm.n,DCF!$B$11,_xlpm.lcx,DCF!$B$19,_xlpm.r0,DCF!$B$37,_xlpm.om0,DCF!$B$39,_xlpm.cx0,DCF!$B$40,_xlpm.da0,DCF!$B$41,_xlpm.dar,DCF!$B$20,_xlpm.tx,DCF!$B$31,_xlpm.sb,DCF!$B$43,_xlpm.nw,DCF!$B$21,_xlpm.gd,N(DCF!$B$22),_xlpm.nc,DCF!$B$47,_xlpm.shs,DCF!$B$6,_xlpm.m,DCF!$B$48,_xlpm.t,_xlfn.SEQUENCE(10),_xlpm.g,_xlpm.gs-(_xlpm.gs-_xlpm.tgr)*(_xlpm.t-1)/9,_xlpm.cum,MMULT(--(_xlpm.t>=TRANSPOSE(_xlpm.t)),LN(1+_xlpm.g)),_xlpm.rev,_xlpm.r0*EXP(_xlpm.cum),_xlpm.prv,_xlpm.r0*EXP(_xlpm.cum-LN(1+_xlpm.g)),_xlpm.lp,IF(_xlpm.t>=_xlpm.n,1,_xlpm.t/_xlpm.n),_xlpm.omt,_xlpm.om0+(_xlpm.om-_xlpm.om0)*_xlpm.lp,_xlpm.dat,_xlpm.da0+(_xlpm.lcx*_xlpm.dar-_xlpm.da0)*_xlpm.lp,_xlpm.cpx,IF((_xlpm.t=1)*(_xlpm.gd>0),_xlpm.gd/_xlpm.rev,_xlpm.cx0+(_xlpm.lcx-_xlpm.cx0)*_xlpm.lp),_xlpm.f,_xlpm.rev*(_xlpm.omt*(1-_xlpm.tx)+_xlpm.dat-_xlpm.cpx+_xlpm.sb)-_xlpm.nw*(_xlpm.rev-_xlpm.prv),_xlpm.pv,SUM(_xlpm.f/(1+_xlpm.w)^(_xlpm.t-0.5*_xlpm.m)),_xlpm.tv,INDEX(_xlpm.f,10)*(1+_xlpm.tgr)/(_xlpm.w-_xlpm.tgr)/(1+_xlpm.w)^10,(_xlpm.pv+_xlpm.tv+_xlpm.nc)/_xlpm.shs)} | D29: {=_xlfn.LET(_xlpm.gs,$B29,_xlpm.om,D$28,_xlpm.w,DCF!$B$7,_xlpm.tgr,DCF!$B$8,_xlpm.n,DCF!$B$11,_xlpm.lcx,DCF!$B$19,_xlpm.r0,DCF!$B$37,_xlpm.om0,DCF!$B$39,_xlpm.cx0,DCF!$B$40,_xlpm.da0,DCF!$B$41,_xlpm.dar,DCF!$B$20,_xlpm.tx,DCF!$B$31,_xlpm.sb,DCF!$B$43,_xlpm.nw,DCF!$B$21,_xlpm.gd,N(DCF!$B$22),_xlpm.nc,DCF!$B$47,_xlpm.shs,DCF!$B$6,_xlpm.m,DCF!$B$48,_xlpm.t,_xlfn.SEQUENCE(10),_xlpm.g,_xlpm.gs-(_xlpm.gs-_xlpm.tgr)*(_xlpm.t-1)/9,_xlpm.cum,MMULT(--(_xlpm.t>=TRANSPOSE(_xlpm.t)),LN(1+_xlpm.g)),_xlpm.rev,_xlpm.r0*EXP(_xlpm.cum),_xlpm.prv,_xlpm.r0*EXP(_xlpm.cum-LN(1+_xlpm.g)),_xlpm.lp,IF(_xlpm.t>=_xlpm.n,1,_xlpm.t/_xlpm.n),_xlpm.omt,_xlpm.om0+(_xlpm.om-_xlpm.om0)*_xlpm.lp,_xlpm.dat,_xlpm.da0+(_xlpm.lcx*_xlpm.dar-_xlpm.da0)*_xlpm.lp,_xlpm.cpx,IF((_xlpm.t=1)*(_xlpm.gd>0),_xlpm.gd/_xlpm.rev,_xlpm.cx0+(_xlpm.lcx-_xlpm.cx0)*_xlpm.lp),_xlpm.f,_xlpm.rev*(_xlpm.omt*(1-_xlpm.tx)+_xlpm.dat-_xlpm.cpx+_xlpm.sb)-_xlpm.nw*(_xlpm.rev-_xlpm.prv),_xlpm.pv,SUM(_xlpm.f/(1+_xlpm.w)^(_xlpm.t-0.5*_xlpm.m)),_xlpm.tv,INDEX(_xlpm.f,10)*(1+_xlpm.tgr)/(_xlpm.w-_xlpm.tgr)/(1+_xlpm.w)^10,(_xlpm.pv+_xlpm.tv+_xlpm.nc)/_xlpm.shs)} | E29: {=_xlfn.LET(_xlpm.gs,$B29,_xlpm.om,E$28,_xlpm.w,DCF!$B$7,_xlpm.tgr,DCF!$B$8,_xlpm.n,DCF!$B$11,_xlpm.lcx,DCF!$B$19,_xlpm.r0,DCF!$B$37,_xlpm.om0,DCF!$B$39,_xlpm.cx0,DCF!$B$40,_xlpm.da0,DCF!$B$41,_xlpm.dar,DCF!$B$20,_xlpm.tx,DCF!$B$31,_xlpm.sb,DCF!$B$43,_xlpm.nw,DCF!$B$21,_xlpm.gd,N(DCF!$B$22),_xlpm.nc,DCF!$B$47,_xlpm.shs,DCF!$B$6,_xlpm.m,DCF!$B$48,_xlpm.t,_xlfn.SEQUENCE(10),_xlpm.g,_xlpm.gs-(_xlpm.gs-_xlpm.tgr)*(_xlpm.t-1)/9,_xlpm.cum,MMULT(--(_xlpm.t>=TRANSPOSE(_xlpm.t)),LN(1+_xlpm.g)),_xlpm.rev,_xlpm.r0*EXP(_xlpm.cum),_xlpm.prv,_xlpm.r0*EXP(_xlpm.cum-LN(1+_xlpm.g)),_xlpm.lp,IF(_xlpm.t>=_xlpm.n,1,_xlpm.t/_xlpm.n),_xlpm.omt,_xlpm.om0+(_xlpm.om-_xlpm.om0)*_xlpm.lp,_xlpm.dat,_xlpm.da0+(_xlpm.lcx*_xlpm.dar-_xlpm.da0)*_xlpm.lp,_xlpm.cpx,IF((_xlpm.t=1)*(_xlpm.gd>0),_xlpm.gd/_xlpm.rev,_xlpm.cx0+(_xlpm.lcx-_xlpm.cx0)*_xlpm.lp),_xlpm.f,_xlpm.rev*(_xlpm.omt*(1-_xlpm.tx)+_xlpm.dat-_xlpm.cpx+_xlpm.sb)-_xlpm.nw*(_xlpm.rev-_xlpm.prv),_xlpm.pv,SUM(_xlpm.f/(1+_xlpm.w)^(_xlpm.t-0.5*_xlpm.m)),_xlpm.tv,INDEX(_xlpm.f,10)*(1+_xlpm.tgr)/(_xlpm.w-_xlpm.tgr)/(1+_xlpm.w)^10,(_xlpm.pv+_xlpm.tv+_xlpm.nc)/_xlpm.shs)} | F29: {=_xlfn.LET(_xlpm.gs,$B29,_xlpm.om,F$28,_xlpm.w,DCF!$B$7,_xlpm.tgr,DCF!$B$8,_xlpm.n,DCF!$B$11,_xlpm.lcx,DCF!$B$19,_xlpm.r0,DCF!$B$37,_xlpm.om0,DCF!$B$39,_xlpm.cx0,DCF!$B$40,_xlpm.da0,DCF!$B$41,_xlpm.dar,DCF!$B$20,_xlpm.tx,DCF!$B$31,_xlpm.sb,DCF!$B$43,_xlpm.nw,DCF!$B$21,_xlpm.gd,N(DCF!$B$22),_xlpm.nc,DCF!$B$47,_xlpm.shs,DCF!$B$6,_xlpm.m,DCF!$B$48,_xlpm.t,_xlfn.SEQUENCE(10),_xlpm.g,_xlpm.gs-(_xlpm.gs-_xlpm.tgr)*(_xlpm.t-1)/9,_xlpm.cum,MMULT(--(_xlpm.t>=TRANSPOSE(_xlpm.t)),LN(1+_xlpm.g)),_xlpm.rev,_xlpm.r0*EXP(_xlpm.cum),_xlpm.prv,_xlpm.r0*EXP(_xlpm.cum-LN(1+_xlpm.g)),_xlpm.lp,IF(_xlpm.t>=_xlpm.n,1,_xlpm.t/_xlpm.n),_xlpm.omt,_xlpm.om0+(_xlpm.om-_xlpm.om0)*_xlpm.lp,_xlpm.dat,_xlpm.da0+(_xlpm.lcx*_xlpm.dar-_xlpm.da0)*_xlpm.lp,_xlpm.cpx,IF((_xlpm.t=1)*(_xlpm.gd>0),_xlpm.gd/_xlpm.rev,_xlpm.cx0+(_xlpm.lcx-_xlpm.cx0)*_xlpm.lp),_xlpm.f,_xlpm.rev*(_xlpm.omt*(1-_xlpm.tx)+_xlpm.dat-_xlpm.cpx+_xlpm.sb)-_xlpm.nw*(_xlpm.rev-_xlpm.prv),_xlpm.pv,SUM(_xlpm.f/(1+_xlpm.w)^(_xlpm.t-0.5*_xlpm.m)),_xlpm.tv,INDEX(_xlpm.f,10)*(1+_xlpm.tgr)/(_xlpm.w-_xlpm.tgr)/(1+_xlpm.w)^10,(_xlpm.pv+_xlpm.tv+_xlpm.nc)/_xlpm.shs)} | G29: {=_xlfn.LET(_xlpm.gs,$B29,_xlpm.om,G$28,_xlpm.w,DCF!$B$7,_xlpm.tgr,DCF!$B$8,_xlpm.n,DCF!$B$11,_xlpm.lcx,DCF!$B$19,_xlpm.r0,DCF!$B$37,_xlpm.om0,DCF!$B$39,_xlpm.cx0,DCF!$B$40,_xlpm.da0,DCF!$B$41,_xlpm.dar,DCF!$B$20,_xlpm.tx,DCF!$B$31,_xlpm.sb,DCF!$B$43,_xlpm.nw,DCF!$B$21,_xlpm.gd,N(DCF!$B$22),_xlpm.nc,DCF!$B$47,_xlpm.shs,DCF!$B$6,_xlpm.m,DCF!$B$48,_xlpm.t,_xlfn.SEQUENCE(10),_xlpm.g,_xlpm.gs-(_xlpm.gs-_xlpm.tgr)*(_xlpm.t-1)/9,_xlpm.cum,MMULT(--(_xlpm.t>=TRANSPOSE(_xlpm.t)),LN(1+_xlpm.g)),_xlpm.rev,_xlpm.r0*EXP(_xlpm.cum),_xlpm.prv,_xlpm.r0*EXP(_xlpm.cum-LN(1+_xlpm.g)),_xlpm.lp,IF(_xlpm.t>=_xlpm.n,1,_xlpm.t/_xlpm.n),_xlpm.omt,_xlpm.om0+(_xlpm.om-_xlpm.om0)*_xlpm.lp,_xlpm.dat,_xlpm.da0+(_xlpm.lcx*_xlpm.dar-_xlpm.da0)*_xlpm.lp,_xlpm.cpx,IF((_xlpm.t=1)*(_xlpm.gd>0),_xlpm.gd/_xlpm.rev,_xlpm.cx0+(_xlpm.lcx-_xlpm.cx0)*_xlpm.lp),_xlpm.f,_xlpm.rev*(_xlpm.omt*(1-_xlpm.tx)+_xlpm.dat-_xlpm.cpx+_xlpm.sb)-_xlpm.nw*(_xlpm.rev-_xlpm.prv),_xlpm.pv,SUM(_xlpm.f/(1+_xlpm.w)^(_xlpm.t-0.5*_xlpm.m)),_xlpm.tv,INDEX(_xlpm.f,10)*(1+_xlpm.tgr)/(_xlpm.w-_xlpm.tgr)/(1+_xlpm.w)^10,(_xlpm.pv+_xlpm.tv+_xlpm.nc)/_xlpm.shs)} | J29: =DCF!$B$19-0.04 | K29: {=_xlfn.LET(_xlpm.gs,DCF!$B$9,_xlpm.om,DCF!$B$10,_xlpm.w,DCF!$B$7,_xlpm.tgr,DCF!$B$8,_xlpm.n,K$28,_xlpm.lcx,$J29,_xlpm.r0,DCF!$B$37,_xlpm.om0,DCF!$B$39,_xlpm.cx0,DCF!$B$40,_xlpm.da0,DCF!$B$41,_xlpm.dar,DCF!$B$20,_xlpm.tx,DCF!$B$31,_xlpm.sb,DCF!$B$43,_xlpm.nw,DCF!$B$21,_xlpm.gd,N(DCF!$B$22),_xlpm.nc,DCF!$B$47,_xlpm.shs,DCF!$B$6,_xlpm.m,DCF!$B$48,_xlpm.t,_xlfn.SEQUENCE(10),_xlpm.g,_xlpm.gs-(_xlpm.gs-_xlpm.tgr)*(_xlpm.t-1)/9,_xlpm.cum,MMULT(--(_xlpm.t>=TRANSPOSE(_xlpm.t)),LN(1+_xlpm.g)),_xlpm.rev,_xlpm.r0*EXP(_xlpm.cum),_xlpm.prv,_xlpm.r0*EXP(_xlpm.cum-LN(1+_xlpm.g)),_xlpm.lp,IF(_xlpm.t>=_xlpm.n,1,_xlpm.t/_xlpm.n),_xlpm.omt,_xlpm.om0+(_xlpm.om-_xlpm.om0)*_xlpm.lp,_xlpm.dat,_xlpm.da0+(_xlpm.lcx*_xlpm.dar-_xlpm.da0)*_xlpm.lp,_xlpm.cpx,IF((_xlpm.t=1)*(_xlpm.gd>0),_xlpm.gd/_xlpm.rev,_xlpm.cx0+(_xlpm.lcx-_xlpm.cx0)*_xlpm.lp),_xlpm.f,_xlpm.rev*(_xlpm.omt*(1-_xlpm.tx)+_xlpm.dat-_xlpm.cpx+_xlpm.sb)-_xlpm.nw*(_xlpm.rev-_xlpm.prv),_xlpm.pv,SUM(_xlpm.f/(1+_xlpm.w)^(_xlpm.t-0.5*_xlpm.m)),_xlpm.tv,INDEX(_xlpm.f,10)*(1+_xlpm.tgr)/(_xlpm.w-_xlpm.tgr)/(1+_xlpm.w)^10,(_xlpm.pv+_xlpm.tv+_xlpm.nc)/_xlpm.shs)} | L29: {=_xlfn.LET(_xlpm.gs,DCF!$B$9,_xlpm.om,DCF!$B$10,_xlpm.w,DCF!$B$7,_xlpm.tgr,DCF!$B$8,_xlpm.n,L$28,_xlpm.lcx,$J29,_xlpm.r0,DCF!$B$37,_xlpm.om0,DCF!$B$39,_xlpm.cx0,DCF!$B$40,_xlpm.da0,DCF!$B$41,_xlpm.dar,DCF!$B$20,_xlpm.tx,DCF!$B$31,_xlpm.sb,DCF!$B$43,_xlpm.nw,DCF!$B$21,_xlpm.gd,N(DCF!$B$22),_xlpm.nc,DCF!$B$47,_xlpm.shs,DCF!$B$6,_xlpm.m,DCF!$B$48,_xlpm.t,_xlfn.SEQUENCE(10),_xlpm.g,_xlpm.gs-(_xlpm.gs-_xlpm.tgr)*(_xlpm.t-1)/9,_xlpm.cum,MMULT(--(_xlpm.t>=TRANSPOSE(_xlpm.t)),LN(1+_xlpm.g)),_xlpm.rev,_xlpm.r0*EXP(_xlpm.cum),_xlpm.prv,_xlpm.r0*EXP(_xlpm.cum-LN(1+_xlpm.g)),_xlpm.lp,IF(_xlpm.t>=_xlpm.n,1,_xlpm.t/_xlpm.n),_xlpm.omt,_xlpm.om0+(_xlpm.om-_xlpm.om0)*_xlpm.lp,_xlpm.dat,_xlpm.da0+(_xlpm.lcx*_xlpm.dar-_xlpm.da0)*_xlpm.lp,_xlpm.cpx,IF((_xlpm.t=1)*(_xlpm.gd>0),_xlpm.gd/_xlpm.rev,_xlpm.cx0+(_xlpm.lcx-_xlpm.cx0)*_xlpm.lp),_xlpm.f,_xlpm.rev*(_xlpm.omt*(1-_xlpm.tx)+_xlpm.dat-_xlpm.cpx+_xlpm.sb)-_xlpm.nw*(_xlpm.rev-_xlpm.prv),_xlpm.pv,SUM(_xlpm.f/(1+_xlpm.w)^(_xlpm.t-0.5*_xlpm.m)),_xlpm.tv,INDEX(_xlpm.f,10)*(1+_xlpm.tgr)/(_xlpm.w-_xlpm.tgr)/(1+_xlpm.w)^10,(_xlpm.pv+_xlpm.tv+_xlpm.nc)/_xlpm.shs)} | M29: {=_xlfn.LET(_xlpm.gs,DCF!$B$9,_xlpm.om,DCF!$B$10,_xlpm.w,DCF!$B$7,_xlpm.tgr,DCF!$B$8,_xlpm.n,M$28,_xlpm.lcx,$J29,_xlpm.r0,DCF!$B$37,_xlpm.om0,DCF!$B$39,_xlpm.cx0,DCF!$B$40,_xlpm.da0,DCF!$B$41,_xlpm.dar,DCF!$B$20,_xlpm.tx,DCF!$B$31,_xlpm.sb,DCF!$B$43,_xlpm.nw,DCF!$B$21,_xlpm.gd,N(DCF!$B$22),_xlpm.nc,DCF!$B$47,_xlpm.shs,DCF!$B$6,_xlpm.m,DCF!$B$48,_xlpm.t,_xlfn.SEQUENCE(10),_xlpm.g,_xlpm.gs-(_xlpm.gs-_xlpm.tgr)*(_xlpm.t-1)/9,_xlpm.cum,MMULT(--(_xlpm.t>=TRANSPOSE(_xlpm.t)),LN(1+_xlpm.g)),_xlpm.rev,_xlpm.r0*EXP(_xlpm.cum),_xlpm.prv,_xlpm.r0*EXP(_xlpm.cum-LN(1+_xlpm.g)),_xlpm.lp,IF(_xlpm.t>=_xlpm.n,1,_xlpm.t/_xlpm.n),_xlpm.omt,_xlpm.om0+(_xlpm.om-_xlpm.om0)*_xlpm.lp,_xlpm.dat,_xlpm.da0+(_xlpm.lcx*_xlpm.dar-_xlpm.da0)*_xlpm.lp,_xlpm.cpx,IF((_xlpm.t=1)*(_xlpm.gd>0),_xlpm.gd/_xlpm.rev,_xlpm.cx0+(_xlpm.lcx-_xlpm.cx0)*_xlpm.lp),_xlpm.f,_xlpm.rev*(_xlpm.omt*(1-_xlpm.tx)+_xlpm.dat-_xlpm.cpx+_xlpm.sb)-_xlpm.nw*(_xlpm.rev-_xlpm.prv),_xlpm.pv,SUM(_xlpm.f/(1+_xlpm.w)^(_xlpm.t-0.5*_xlpm.m)),_xlpm.tv,INDEX(_xlpm.f,10)*(1+_xlpm.tgr)/(_xlpm.w-_xlpm.tgr)/(1+_xlpm.w)^10,(_xlpm.pv+_xlpm.tv+_xlpm.nc)/_xlpm.shs)} | N29: {=_xlfn.LET(_xlpm.gs,DCF!$B$9,_xlpm.om,DCF!$B$10,_xlpm.w,DCF!$B$7,_xlpm.tgr,DCF!$B$8,_xlpm.n,N$28,_xlpm.lcx,$J29,_xlpm.r0,DCF!$B$37,_xlpm.om0,DCF!$B$39,_xlpm.cx0,DCF!$B$40,_xlpm.da0,DCF!$B$41,_xlpm.dar,DCF!$B$20,_xlpm.tx,DCF!$B$31,_xlpm.sb,DCF!$B$43,_xlpm.nw,DCF!$B$21,_xlpm.gd,N(DCF!$B$22),_xlpm.nc,DCF!$B$47,_xlpm.shs,DCF!$B$6,_xlpm.m,DCF!$B$48,_xlpm.t,_xlfn.SEQUENCE(10),_xlpm.g,_xlpm.gs-(_xlpm.gs-_xlpm.tgr)*(_xlpm.t-1)/9,_xlpm.cum,MMULT(--(_xlpm.t>=TRANSPOSE(_xlpm.t)),LN(1+_xlpm.g)),_xlpm.rev,_xlpm.r0*EXP(_xlpm.cum),_xlpm.prv,_xlpm.r0*EXP(_xlpm.cum-LN(1+_xlpm.g)),_xlpm.lp,IF(_xlpm.t>=_xlpm.n,1,_xlpm.t/_xlpm.n),_xlpm.omt,_xlpm.om0+(_xlpm.om-_xlpm.om0)*_xlpm.lp,_xlpm.dat,_xlpm.da0+(_xlpm.lcx*_xlpm.dar-_xlpm.da0)*_xlpm.lp,_xlpm.cpx,IF((_xlpm.t=1)*(_xlpm.gd>0),_xlpm.gd/_xlpm.rev,_xlpm.cx0+(_xlpm.lcx-_xlpm.cx0)*_xlpm.lp),_xlpm.f,_xlpm.rev*(_xlpm.omt*(1-_xlpm.tx)+_xlpm.dat-_xlpm.cpx+_xlpm.sb)-_xlpm.nw*(_xlpm.rev-_xlpm.prv),_xlpm.pv,SUM(_xlpm.f/(1+_xlpm.w)^(_xlpm.t-0.5*_xlpm.m)),_xlpm.tv,INDEX(_xlpm.f,10)*(1+_xlpm.tgr)/(_xlpm.w-_xlpm.tgr)/(1+_xlpm.w)^10,(_xlpm.pv+_xlpm.tv+_xlpm.nc)/_xlpm.shs)} | O29: {=_xlfn.LET(_xlpm.gs,DCF!$B$9,_xlpm.om,DCF!$B$10,_xlpm.w,DCF!$B$7,_xlpm.tgr,DCF!$B$8,_xlpm.n,O$28,_xlpm.lcx,$J29,_xlpm.r0,DCF!$B$37,_xlpm.om0,DCF!$B$39,_xlpm.cx0,DCF!$B$40,_xlpm.da0,DCF!$B$41,_xlpm.dar,DCF!$B$20,_xlpm.tx,DCF!$B$31,_xlpm.sb,DCF!$B$43,_xlpm.nw,DCF!$B$21,_xlpm.gd,N(DCF!$B$22),_xlpm.nc,DCF!$B$47,_xlpm.shs,DCF!$B$6,_xlpm.m,DCF!$B$48,_xlpm.t,_xlfn.SEQUENCE(10),_xlpm.g,_xlpm.gs-(_xlpm.gs-_xlpm.tgr)*(_xlpm.t-1)/9,_xlpm.cum,MMULT(--(_xlpm.t>=TRANSPOSE(_xlpm.t)),LN(1+_xlpm.g)),_xlpm.rev,_xlpm.r0*EXP(_xlpm.cum),_xlpm.prv,_xlpm.r0*EXP(_xlpm.cum-LN(1+_xlpm.g)),_xlpm.lp,IF(_xlpm.t>=_xlpm.n,1,_xlpm.t/_xlpm.n),_xlpm.omt,_xlpm.om0+(_xlpm.om-_xlpm.om0)*_xlpm.lp,_xlpm.dat,_xlpm.da0+(_xlpm.lcx*_xlpm.dar-_xlpm.da0)*_xlpm.lp,_xlpm.cpx,IF((_xlpm.t=1)*(_xlpm.gd>0),_xlpm.gd/_xlpm.rev,_xlpm.cx0+(_xlpm.lcx-_xlpm.cx0)*_xlpm.lp),_xlpm.f,_xlpm.rev*(_xlpm.omt*(1-_xlpm.tx)+_xlpm.dat-_xlpm.cpx+_xlpm.sb)-_xlpm.nw*(_xlpm.rev-_xlpm.prv),_xlpm.pv,SUM(_xlpm.f/(1+_xlpm.w)^(_xlpm.t-0.5*_xlpm.m)),_xlpm.tv,INDEX(_xlpm.f,10)*(1+_xlpm.tgr)/(_xlpm.w-_xlpm.tgr)/(1+_xlpm.w)^10,(_xlpm.pv+_xlpm.tv+_xlpm.nc)/_xlpm.shs)}
